Workbook

Sheet Summary master
A1: PRODUCT RANGE | F1: Storage facility | K1: Ordered | N1: Raw Materials | W1: Packaging
A2: THE HERBAL HORSE | B2: Code | C2: Size | D2: Total | E2: Reorder point | G2: 88 (units) | H2: South Storage | I2: THH&P | J2: Cases at 88s | K2: @ manufacturer? Y/N | L2: @ packer? Y/N | N2: Kelp | O2: Chia seeds | P2: Phktn/Nanchlis | Q2: Diatomaceous EA | R2: Rooibos powder | S2: Cedarwood oil | U2: COST | W2: Jars | X2: Sydney bottle | Y2: Flip top cap | Z2: Boston bottle | AA2: Mini Trigger | AB2: Sponges | AC2: Cases for NP chews | AD2: Cases for HP chews | AE2: Cases for 200g HP packs | AF2: Cases for shampoo, spray and CG | AG2: Batch Labels | AH2: Case Labels
A3: Calm Mix | B3: CM500 | C3: 500g | D3: =G3+I3 -> 28 | E3: ='REORDER POINT'!M33 -> 24.863014 | G3: =CM!A48 -> 0 | H3: =CM!#REF! -> #REF! | I3: =CM!A7 -> 28 | U3: =CM!B103 -> 136.26
B4: CM2000 | C4: 2Kg | D4: =G4+I4 -> 1 | E4: ='REORDER POINT'!M34 -> 5.1369863 | G4: =CM!A52 -> 0 | H4: =CM!#REF! -> #REF! | I4: =CM!A25 -> 1 | U4: =CM!B104 -> 454.29
A5: Digestion Mix | B5: DM500 | C5: 500g | D5: =G5+I5 -> 29 | E5: ='REORDER POINT'!M35 -> 5.3424658 | G5: =DM!A48 -> 0 | H5: =DM!#REF! -> #REF! | I5: =DM!A7 -> 29 | U5: =DM!#REF! -> #REF!
B6: DM2000 | C6: 2Kg | D6: =G6+I6 -> 5 | E6: ='REORDER POINT'!M36 -> 2.260274 | G6: =DM!A52 -> 0 | H6: =DM!#REF! -> #REF! | I6: =DM!A25 -> 5 | U6: =DM!#REF! -> #REF!
A7: Stamina Mix | B7: SM500 | C7: 500g | D7: =G7+I7 -> 9 | E7: ='REORDER POINT'!M37 -> 4.3150685 | G7: =SM!A48 -> 0 | H7: =SM!#REF! -> #REF! | I7: =SM!A7 -> 9 | U7: =SM!#REF! -> #REF!
B8: SM2000 | C8: 2Kg | D8: =G8+I8 -> 1 | E8: ='REORDER POINT'!M38 -> 1.0273973 | G8: =SM!A52 -> 0 | H8: =SM!#REF! -> #REF! | I8: =SM!A25 -> 1 | U8: =SM!#REF! -> #REF!
A9: Farriers’ Mix | B9: FM500 | C9: 500g | D9: =G9+I9 -> 2 | E9: ='REORDER POINT'!M39 -> 11.917808 | G9: =FM!A48 -> 0 | H9: =FM!#REF! -> #REF! | I9: =FM!A7 -> 2 | U9: =FM!#REF! -> #REF!
B10: FM2000 | C10: 2Kg | D10: =G10+I10 -> 0 | E10: ='REORDER POINT'!M40 -> 7.1917808 | G10: =FM!A52 -> 0 | H10: =FM!#REF! -> #REF! | I10: =FM!A25 -> 0 | U10: =FM!#REF! -> #REF!
A11: Immune Mix | B11: IM500 | C11: 500g | D11: =G11+I11 -> 30 | E11: ='REORDER POINT'!M41 -> 3.0821918 | G11: =IM!A50 -> 0 | H11: =IM!#REF! -> #REF! | I11: =IM!A8 -> 30 | U11: =IM!#REF! -> #REF!
B12: IM2000 | C12: 2Kg | D12: =G12+I12 -> 0 | E12: ='REORDER POINT'!M42 -> 1.4383562 | G12: =IM!A54 -> 0 | H12: =IM!#REF! -> #REF! | I12: =IM!A25 -> 0 | U12: =IM!#REF! -> #REF!
A13: Itch Mix | B13: ItM500 | C13: 500g | D13: =G13+I13 -> 2 | E13: ='REORDER POINT'!M43 -> 7.8082192 | G13: =ItM!A48 -> 0 | H13: =ItM!#REF! -> #REF! | I13: =ItM!A7 -> 2 | U13: =ItM!B102 -> 159.38
B14: ItM2000 | C14: 2Kg | D14: =G14+I14 -> 5 | E14: ='REORDER POINT'!M44 -> 3.6986301 | G14: =ItM!A52 -> 0 | H14: =ItM!#REF! -> #REF! | I14: =ItM!A25 -> 5 | U14: =ItM!B103 -> 543.53
A15: Mare mix | B15: MM250 | C15: 250g | D15: =G15+I15 -> 8 | E15: ='REORDER POINT'!M45 -> 5.3424658 | G15: =MM!A48 -> 0 | H15: =MM!#REF! -> #REF! | I15: =MM!A7 -> 8 | U15: =MM!#REF! -> #REF!
B16: MM2000 | C16: 2Kg | D16: =G16+I16 -> 9 | G16: 0 | H16: =MM!#REF! -> #REF! | I16: =MM!A25 -> 9 | U16: =MM!#REF! -> #REF!
A17: Rejuven Mix | B17: RM500 | C17: 500g | D17: =G17+I17 -> 8 | E17: ='REORDER POINT'!M47 -> 9.6575342 | G17: =RM!A48 -> 0 | H17: =RM!#REF! -> #REF! | I17: =RM!A7 -> 8 | U17: =RM!#REF! -> #REF!
B18: RM2000 | C18: 2Kg | D18: =G18+I18 -> 3 | E18: ='REORDER POINT'!M48 -> 0.82191781 | G18: =RM!A52 -> 0 | H18: =RM!#REF! -> #REF! | I18: =RM!A25 -> 3 | U18: =RM!#REF! -> #REF!
A19: Ultimate Mix | B19: UM500 | C19: 500g | D19: =G19+I19 -> 4 | E19: ='REORDER POINT'!M51 -> 3.9041096 | G19: =UM!A48 -> 0 | H19: =UM!#REF! -> #REF! | I19: =UM!A7 -> 4 | U19: =UM!#REF! -> #REF!
B20: UM2000 | C20: 2Kg | D20: =G20+I20 -> 8 | E20: ='REORDER POINT'!M52 -> 2.0547945 | G20: =UM!A52 -> 0 | H20: =UM!#REF! -> #REF! | I20: =UM!A25 -> 8 | U20: =UM!#REF! -> #REF!
A22: THE HERBAL PET | B22: Code | C22: Size | D22: Total | G22: 88s | H22: South Storage | I22: THH&P | J22: Cases at 88s | K22: @ manufacturer? Y/N | L22: @ packer? Y/N | N22: Kelp | O22: Chia seeds | P22: Phktn/Nanchlis | Q22: Diatomaceous EA | R22: Rooibos powder | S22: Cedarwood oil | U22: COST | W22: CCTubes | X22: Sydney bottle | Y22: Flip top cap | Z22: Boston bottle | AA22: Mini Trigger | AB22: Sponges | AC22: Cases for NP chews | AD22: Cases for HP chews | AE22: Cases for 200g HP packs | AF22: Cases for shampoo, spray and CG | AG22: Batch Labels | AH22: Case Labels
A23: Allergy Formula | B23: AF200 | C23: 200g | D23: =G23+I23 -> 364 | E23: ='REORDER POINT'!N3*6 -> 331.0274 | G23: =AF!A48 -> 90 | H23: =AF!A48 -> 90 | I23: =AF!A7 -> 274 | J23: =G23/6 -> 15 | N23: 3.25 | U23: =AF!D109 -> 0 | W23: =PACKAGING!C8 -> 0 | AE23: 1750
B24: AF500 | C24: 500g | D24: =G24+I24 -> 5 | E24: ='REORDER POINT'!N55 -> 2.2260274 | G24: 0 | H24: =AF!#REF! -> #REF! | I24: =AF!A25 -> 5 | J24: 0
A25: Everypet Formula | B25: EF200 | C25: 200g | D25: =G25+I25 -> 222 | E25: ='REORDER POINT'!N4*6 -> 111.36986 | G25: =EF!A48 -> 72 | H25: =EF!A48 -> 72 | I25: =EF!A7 -> 150 | J25: =G25/6 -> 12 | N25: 3.25 | R25: 70.615 | U25: =EF!D131 -> 0 | W25: =PACKAGING!C9 -> 0 | AE25: =AE23 -> 1750
B26: EF500 | C26: 500g | D26: =G26+I26 -> 9 | E26: ='REORDER POINT'!N56 -> 0.92465753 | G26: 0 | H26: =EF!A69 -> 0 | I26: =EF!A25 -> 9 | J26: 0
A27: Joint Formula | B27: JF200 | C27: 200g | D27: =G27+I27 -> 469 | E27: ='REORDER POINT'!N5*6 -> 302.26027 | G27: =JF!A48 -> 48 | H27: =JF!A48 -> 48 | I27: =JF!A7 -> 421 | J27: =G27/6 -> 8 | N27: 3.25 | U27: =JF!D131 -> 0 | W27: =PACKAGING!C10 -> 0 | AE27: =AE23 -> 1750
B28: JF500 | C28: 500g | D28: =G28+I28 -> 9 | E28: ='REORDER POINT'!N57 -> 0.99315068 | G28: 0 | H28: =JF!A69 -> 0 | I28: =JF!A25 -> 9 | J28: 0
A29: HP Omega 3 Formula | B29: HP O3F75 | C29: 75g | D29: =G29+I29 -> 204 | E29: ='REORDER POINT'!N6*6 -> 19.315068 | G29: 0 | H29: =O3F!#REF! -> #REF! | I29: =O3F!A7 -> 204 | J29: 0 | N29: 3.25 | O29: 20 | P29: 13.5 | Q29: 4.29 | U29: =O3F!D64 -> 0 | W29: =PACKAGING!C19 -> 0 | AD29: 50
A30: ParaCleanse Formula | B30: PCF240 | C30: 240g | D30: =G30+I30 -> 0 | E30: ='REORDER POINT'!N7*6 -> 34.931507 | G30: 0 | H30: =PCF!#REF! -> #REF! | I30: =PCF!A15 -> 0 | J30: 0 | N30: 3.25 | W30: =PACKAGING!C84 -> 10 | AD30: 50
B31: PCF500 | C31: 500g | D31: =G31+I31 -> 0 | E31: ='REORDER POINT'!N58 -> 0.17123288 | G31: 0 | H31: =PCF!#REF! -> #REF! | I31: =PCF!A30 -> 0 | J31: 0 | U31: =PCF!D80 -> 0 | W31: =PACKAGING!C11 -> 50 | AE31: =AE23 -> 1750
A32: Serenity Formula | B32: SF200 | C32: 200g | D32: =G32+I32 -> 133 | E32: ='REORDER POINT'!N8*6 -> 146.09589 | G32: =SF!A55 -> 12 | H32: =SF!A55 -> 12 | I32: =SF!A20 -> 121 | J32: =G32/6 -> 2 | W32: =PACKAGING!C84 -> 10 | AD32: 50
B33: SF500 | C33: 500g | D33: =G33+I33 -> 3 | E33: ='REORDER POINT'!N59 -> 0.4109589 | G33: 0 | H33: =SF!#REF! -> #REF! | I33: =SF!A35 -> 3 | J33: 0 | U33: =SF!D114 -> 0 | W33: =PACKAGING!C12 -> 0 | AE33: =AE23 -> 1750
A34: HP Allergy Care chews | B34: HPACC30 | C34: 30 | D34: =G34+I34 -> 224 | E34: ='REORDER POINT'!N10*12 -> 736.43836 | G34: 0 | H34: 0 | I34: ='ACC30'!A7 -> 224 | J34: 0
A35: HP Calming chews | B35: HPCC30 | C35: 30 | D35: =G35+I35 -> 331 | E35: ='REORDER POINT'!N11*12 -> 534.24658 | G35: 0 | H35: ='CCH30'!A49 -> 0 | I35: ='CCH30'!A7 -> 331 | J35: 0
B36: HPCCH150 | C36: 150 | D36: =G36+I36 -> 7 | E36: 5 | I36: ='CCH30'!A26 -> 7 | J36: 0
A37: HP Joint Care chews | B37: HPJCC30 | C37: 30 | D37: =G37+I37 -> 116 | E37: ='REORDER POINT'!N12*12 -> 154.10959 | G37: 0 | H37: ='JCC30'!A48 -> 0 | I37: ='JCC30'!A7 -> 116 | J37: 0
A38: HP Tick & Flea chews | B38: HPTFC30 | C38: 30 | D38: =G38+I38 -> 64 | E38: ='REORDER POINT'!N13*12 -> 51.369863 | G38: 0 | H38: ='TFC30'!A48 -> 0 | I38: ='TFC30'!A7 -> 64 | J38: 0
B39: HPTFC150 | C39: 150 | D39: =G39+I39 -> 4 | E39: 5 | I39: ='TFC30'!A25 -> 4 | J39: 0
A40: HP Natural Tick & Flea spray | B40: HPNTFS200 | C40: 200mL | D40: =G40+I40 -> 626 | E40: ='REORDER POINT'!N14*12 -> 71.506849 | G40: 0 | H40: =NTFS200!A48 -> 0 | I40: =NTFS200!A7 -> 626 | J40: 0
A42: NUTRIPHASE | B42: Code | C42: Size | D42: Total | E42: Reorder point (units) | G42: 88s | H42: South Storage | I42: THH&P | J42: Cases at 88s | K42: @ manufacturer? Y/N | L42: @ packer? Y/N | N42: Kelp | O42: Chia seeds | P42: Phktn/Nanchlis | Q42: Diatomaceous EA | R42: Rooibos powder | S42: Cedarwood oil | U42: COST | W42: Vitamin Bottle and Cap | X42: Sydney bottle | Y42: Flip top cap | Z42: Boston bottle | AA42: Mini Trigger | AB42: Sponges | AC42: Cases for NP chews | AD42: Cases for HP chews | AE42: Cases for 200g HP packs | AF42: Cases for shampoo, spray and CG | AG42: Batch Labels | AH42: Case Labels
...

Sheet RAW MATERIALS
A1: RAW MATERIALS | G1: SOH | L1: DETAILS
A2: ITEM: | C2: USED IN | D2: TOTAL | E2: Reorder point | F2: Ordered? | G2: THHP | H2: Storage | I2: Zinchar | J2: NM | K2: SDK | L2: Supplier | M2: Price | N2: MOQ | O2: Lead Time
A3: We supply
A4: Cedarwood oil | C4: Nutriphase and Herbal Pet Tick & Flea spray 4.2% (8.4kg per 1000 bottles) | D4: 5.6 | E4: 9 | J4: 5.6kg (14.07kg after po600 - 8.4 for po620 = 5.6) ( 19.11kg after po559 - 5.04 for po600 = 14.07) EXP 12/2026 | L4: Avi Naturals +91 70423 63832 | N4: 20kg | O4: 3 months
A5: Diatomaceous earth (feed grade) | C5: 11.3kg per 20kg batch | D5: =SUM(G5:K5) -> 0 | E5: 12 | F5: exp 4/23 | L5: Voerdokter, GRF | M5: R110 for 10kg | N5: 10kg | O5: 2 weeks
A6: Kelp | C6: Zinchar AC 20kg per batch | D6: 22.67 | E6: 25 | I6: 23.1 (25kg sent 20/11/2025, 1.9 KG USED PO608) | L6: Raw Kelp, Taurus | M6: N/A | N6: N/A | O6: N/A
A7: Phytoplankton/Nannochloropsis (drying) | C7: Omega 3 Formula 10% | D7: 2.967 | E7: 2 | G7: 0 | J7: 2.967kg after po542 | L7: Lyphar | M7: USD 1709 per 25kg incl shipping, R8641 duties | N7: 25kg | O7: 3 months
A8: Omega 3 powder | C8: JC 2.5kg per batch | D8: 0.505 | E8: 2.5 | I8: 0.5 (1kg in stock, ordered 2kg from brenntag, will use 2.5kg po574) | L8: Brenntag
A10: Bulk tablets/powder
A11: Allergy Care chews | G11: 0 | I11: 23450 after po636 | L11: Zinchar
A12: Calming chews | G12: ='CCH30'!#REF! -> #REF! | I12: 24800 after po632 | L12: Zinchar
A13: Joint Care chews | I13: 0 after po612 | L13: Zinchar
A14: Tick & Flea chews | I14: 38000 after po635 | L14: Zinchar
A15: Allergy Formula | L15: Nutrimed
A16: Joint Formula | L16: Nutrimed
A17: Omega 3 Formula | G17: 2.1 | L17: Nutrimed
A18: Serenity Formula | L18: Nutrimed
A19: Tearstain Formula | L19: Nutrimed
A20: Collagen gravy | G20: 21 | L20: Nutrimed
A21: Tick & Flea spray kg | L21: Nutrimed
A23: No longer ordered
A24: Chia seeds | D24: =SUM(G24:K24) -> 0 | F24: exp 8/23 | I24: 0 | L24: Absolute Organix | M24: 105.89 | N24: 1kg | O24: 3 days
A25: Rooibos powder | D25: =SUM(G25:K25) -> 0 | J25: not supplying | L25: THHP | M25: N/A | N25: N/A | O25: N/A
A26: Instant Dry Yeast | J26: 1.25 (7.5kg after po566, - 6.25 po625 = 1.25)
A27: Conditioning chews | G27: =#REF! -> #REF! | L27: Zinchar

Sheet PACKAGING
A1: PACKAGING: | F1: SOH | N1: DETAILS
B2: ITEM: | C2: TOTAL | D2: Reorder point | E2: Ordered? | F2: THH | G2: Projetech | H2: Storage | I2: Zinchar | J2: Pelchem | K2: GEP | L2: Nutrimed | M2: SDK | N2: Supplier | O2: Price | P2: MOQ | Q2: Lead Time
A3: Ordered by us
B4: 24/410 all plastic mini trigger natural from Hong Kong triggers with tube | D4: 3000 | L4: 10100 (2400 after po559 - 600 po600 - 1000 po620 =800 + 9300 del 24/2/26 = 10100) | N4: Hong Kong triggers | O4: 2.50 | P4: 10000 | Q4: 8 weeks
B5: White Vitamin Bottle 125ML WHITE TABLET CONTAINER 38MM, 324/ BOX | C5: =SUM(F5:M5) -> 0 | D5: per batch | F5: 0 | I5: 120 after po632 (212 in stock, ordered 648, using 840 po632 plus sent 100 from hh) | N5: Schaldor Plastics | O5: 1.63 | Q5: 2 weeks
B6: 38MM BLACK TABLET CAP WITH PS LINER | C6: =SUM(F6:M6) -> 0 | D6: 1000 | F6: 0 | I6: 113 after po632 (282 in stock, ordered 648 po633, using 840 po632, sent 23 from hh) | N6: Schaldor Plastics | O6: 1.53 | Q6: 2 weeks
B7: 75.8mm Dia / DELTASEAL | C7: =SUM(F7:M7) -> 1117 | L7: 1117 | N7: Convertacor | O7: 0.95 | Q7: 3 weeks
B8: Allergy Formula 200g Cores 76.2 mm x 105mm - tubes wrapped with print (full colour)and removable cardboard cap to fit | C8: =SUM(G8:M8) -> 0 | D8: 500 | L8: 80 (560 after po598) - 480 (po618) = 80 | N8: Murrun | O8: USD0.66 | Q8: 16 weeks
B9: Everypet Formula 200g Cores 76.2 mm x 105mm - tubes wrapped with print (full colour)and removable cardboard cap to fit | C9: =SUM(F9:M9) -> 0 | D9: 500 | L9: 1026 (735 after repeated po543, 507 del 1/8 = 1242 - 216 (po627) = 1026) | N9: Murrun | O9: USD0.66 | Q9: 16 weeks
B10: Joint Formula 200g Cores 76.2 mm x 105mm - tubes wrapped with print (full colour)and removable cardboard cap to fit | C10: =SUM(F10:M10) -> 0 | D10: 500 | K10: 18 lids,48 no lids | L10: 485 (380 after po567 + 105 from hh 23/1/26) | N10: Murrun | O10: USD0.66 | Q10: 16 weeks
B11: Paracleanse Formula 240g Cores 76.2 mm x 105mm - tubes wrapped with print (full colour)and removable cardboard cap to fit | C11: =SUM(F11:M11) -> 50 | D11: 500 | K11: 50 | L11: 160 after after po569 - nb cloves removed, update artwork to murrun, cross out for now | N11: Murrun | O11: USD0.66 | Q11: 16 weeks
B12: Serenity Formula 200g Cores 76.2 mm x 105mm - tubes wrapped with print (full colour)and removable cardboard cap to fit | C12: =SUM(F12:M12) -> 0 | D12: 500 | L12: 779 (578 after po568, 501 del 1/8 = 1079. 1079 - 300 (po609)) | N12: Murrun | O12: USD0.66 | Q12: 16 weeks
B13: Seal Size: L05400-DELTA-SEAL 54mm Dia | C13: =SUM(F13:M13) -> 0 | I13: 6028 (800 in stock, sent 208, 7000 ordered for hh, minus 840 (po632) and minus 400 (po635) minus 740 po636) | L13: 149 (118 after po542. sent 210 27/11. - 179 po610) | N13: Convertacor | O13: 0.6721 | Q13: 3 weeks
B14: HP Allergy Care chews 30 Cores 53mm x 73mm - tubes wrapped with print (full colour) and removable cardboard cap to fit | C14: =SUM(F14:M14) -> 17 | D14: 100 | I14: outstanding 740 for po636. 8 after po608 (748-740) | K14: 17 | N14: Murrun | O14: USD0.58 | P14: PO0382 @ GEP for 1000
B15: HP Calming chews 30 Cores 53mm x 73mm - tubes wrapped with print (full colour) and removable cardboard cap to fit | C15: =SUM(F15:M15) -> 0 | D15: 100 | I15: 1049 (1510 after po554, 999 del 1/8 = 2509. minus 900 (po601) = 1609 minus 560 (po615) = 1049) | K15: 0 | N15: Murrun | O15: USD0.58 | P15: PO0382 @ GEP for 1000
B16: HP Joint Care chews 30 Cores 53mm x 73mm - tubes wrapped with print (full colour) and removable cardboard cap to fit | C16: =SUM(F16:M16) -> 0 | D16: 100 | I16: 1570 after po0503, 507 del 1/8 = 2077 | N16: Murrun | O16: USD0.58 | P16: PO0382 @ GEP for 1000
B17: HP Tick & Flea chews 30 Cores 53mm x 73mm - tubes wrapped with print (full colour) and removable cardboard cap to fit | C17: =SUM(F17:M17) -> 0 | D17: 100 | I17: 759 (1159 minus 400 po635) | K17: 0 | N17: Murrun | O17: USD0.58 | P17: PO0382 @ GEP for 1000
B18: HP Collagen Gravy 90g Cores 53mm x 105mm - tubes wrapped with print (full colour) and removable cardboard cap to fit | L18: 0
B19: HP Omega 3 Formula 75g Cores 53mm x 73mm - tubes wrapped with print (full colour) and removable cardboard cap to fit | C19: =SUM(G19:M19) -> 0 | D19: 100 | L19: 255 after po614 (500-245) | N19: Murrun | O19: USD0.58
B20: LNPCH, Label Nutriphase chews 60mm x 150mm roll of 1000 for ALLERGY CARE CHEWS | C20: =SUM(F20:M20) -> 3000 | F20: 3000 | I20: 830 (need 170, sent 1000 14/1/26, =830 after po611) | N20: Rebsons | O20: 783.7
B21: LNPCH, Label Nutriphase chews 60mm x 150mm roll of 1000 for CALMING CHEWS | C21: =SUM(F21:M21) -> 3000 | F21: 3000 | I21: 265 (105 after po554, sending 1000 12/3, using 840 po632, 265 left) | N21: Rebsons | O21: 783.7
B22: LNPCH, Label Nutriphase chews 60mm x 150mm roll of 1000 for JOINT CARE CHEWS | C22: =SUM(F22:M22) -> 3000 | F22: 3000 | I22: 950 (need 50, sent 1000 14/1/26, =950 after po612) | N22: Rebsons | O22: 783.7
B23: LNPCH, Label Nutriphase chews 60mm x 150mm roll of 1000 for TICK & FLEA CHEWS | C23: =SUM(F23:M23) -> 2241 | F23: 1000 | I23: 1241 | N23: Rebsons | O23: 783.7
B24: LNPTFS, Label Nutriphase TF spray 90 x 150mm roll of 1000 for TICK & FLEA SPRAY | C24: =SUM(F24:M24) -> 3000 | F24: 3000 | L24: 410 (430 after po518+1000-600 po600 = 830 - 420 po620) | M24: 0 | N24: Rebsons | O24: 2585.3
B25: LNPTFS, Label HERBAL PET TF spray 90 x 150mm roll of 1000 for TICK & FLEA SPRAY | C25: =SUM(F25:M25) -> 0 | L25: 920 (400? in stock after po559 - 480 +1000 ordered 23/1/26 = 920) | M25: 0 | N25: Labels by Rusbar | O25: 2580
B26: Calm Mix front label | C26: =SUM(F26:M26) -> 0 | L26: 815 (865 minus 50 po637 = 815) | N26: Labels by Rusbar | O26: 2.1504
B27: Calm Mix 500g back label | C27: =SUM(F27:M27) -> 0 | L27: 640 (680 minus 40 po637 = 640) | N27: Labels by Rusbar | O27: 2.1504
B28: Calm Mix 2kg back label | C28: =SUM(F28:M28) -> 0 | L28: 175 (185 minus 10 po637 = 175 ) | N28: Labels by Rusbar | O28: 2.1504
B29: Stamina Mix front label | C29: =SUM(F29:M29) -> 0 | N29: Labels by Rusbar | O29: 2.1504
B30: Stamina Mix 500g back label | C30: =SUM(F30:M30) -> 0 | N30: Labels by Rusbar | O30: 2.1504
B31: Stamina Mix 2kg back label | C31: =SUM(F31:M31) -> 0 | N31: Labels by Rusbar | O31: 2.1504
B32: Farriers’ Mix front label | C32: =SUM(F32:M32) -> 0 | L32: 425 (500 ordered po605 minus 35 po604 minus 40 po631) | N32: Labels by Rusbar | O32: 2.1504
B33: Farriers’ Mix 500g back label | C33: =SUM(F33:M33) -> 0 | L33: 310 (350 ordered po605 minus 20 po604 - 20 po631) | N33: Labels by Rusbar | O33: 2.1504
B34: Farriers’ Mix 2kg back label | C34: =SUM(F34:M34) -> 0 | L34: 115 (150 ordered po605 minus 15 po604 - 20 po631) | N34: Labels by Rusbar | O34: 2.1504
B35: Immune Mix front label | C35: =SUM(F35:M35) -> 0 | N35: Labels by Rusbar | O35: 2.1504
B36: Immune Mix 500g back label | C36: =SUM(F36:M36) -> 0 | N36: Labels by Rusbar | O36: 2.1504
B37: Immune Mix 2kg back label | C37: =SUM(F37:M37) -> 0 | N37: Labels by Rusbar | O37: 2.1504
B38: Itch Mix front label | C38: =SUM(F38:M38) -> 0 | L38: 905 (955- 50 po 640) | N38: Labels by Rusbar | O38: 2.1504
B39: Itch Mix 500g back label | C39: =SUM(F39:M39) -> 0 | L39: 450 (460-40 po640) | N39: Labels by Rusbar | O39: 2.1504
B40: Itch Mix 2kg back label | C40: =SUM(F40:M40) -> 0 | L40: 475 after po 593 (485-10 po 640) | N40: Labels by Rusbar | O40: 2.1504
...

Sheet CALCULATIONS
C3: 100kg MIXES from ASHKAN | G3: 100kg MARE MIX from ASHKAN
C4: 2kg | D4: 500g | E4: 100kg | G4: 2kg | H4: 1kg | I4: 250g | J4: 100kg
C5: 1 | D5: 196 | E5: =C5*2000+D5*500 -> 100000 | H5: 1 | I5: 396 | J5: =G5*2000+H5*1000+I5*250 -> 100000
C6: 2 | D6: 192 | E6: =C6*2000+D6*500 -> 100000 | H6: 2 | I6: 392 | J6: =G6*2000+H6*1000+I6*250 -> 100000
C7: 3 | D7: 188 | E7: =C7*2000+D7*500 -> 100000 | H7: 3 | I7: 388 | J7: =G7*2000+H7*1000+I7*250 -> 100000
C8: 4 | D8: 184 | E8: =C8*2000+D8*500 -> 100000 | H8: 4 | I8: 384 | J8: =G8*2000+H8*1000+I8*250 -> 100000
C9: 5 | D9: 180 | E9: =C9*2000+D9*500 -> 100000 | H9: 5 | I9: 380 | J9: =G9*2000+H9*1000+I9*250 -> 100000
C10: 6 | D10: 176 | E10: =C10*2000+D10*500 -> 100000 | H10: 6 | I10: 376 | J10: =G10*2000+H10*1000+I10*250 -> 100000
C11: 7 | D11: 172 | E11: =C11*2000+D11*500 -> 100000 | H11: 7 | I11: 372 | J11: =G11*2000+H11*1000+I11*250 -> 100000
C12: 8 | D12: 168 | E12: =C12*2000+D12*500 -> 100000 | H12: 8 | I12: 368 | J12: =G12*2000+H12*1000+I12*250 -> 100000
C13: 9 | D13: 164 | E13: =C13*2000+D13*500 -> 100000 | H13: 9 | I13: 364 | J13: =G13*2000+H13*1000+I13*250 -> 100000
C14: 10 | D14: 160 | E14: =C14*2000+D14*500 -> 100000 | H14: 10 | I14: 360 | J14: =G14*2000+H14*1000+I14*250 -> 100000
C15: 11 | D15: 156 | E15: =C15*2000+D15*500 -> 100000 | G15: 1 | H15: 9 | I15: 356 | J15: =G15*2000+H15*1000+I15*250 -> 100000
C16: 12 | D16: 152 | E16: =C16*2000+D16*500 -> 100000 | G16: 2 | H16: 8 | I16: 352 | J16: =G16*2000+H16*1000+I16*250 -> 100000
C17: 13 | D17: 148 | E17: =C17*2000+D17*500 -> 100000 | G17: 3 | H17: 7 | I17: 348 | J17: =G17*2000+H17*1000+I17*250 -> 100000
C18: 14 | D18: 144 | E18: =C18*2000+D18*500 -> 100000 | G18: 4 | H18: 6 | I18: 344 | J18: =G18*2000+H18*1000+I18*250 -> 100000
C19: 15 | D19: 140 | E19: =C19*2000+D19*500 -> 100000 | G19: 5 | H19: 5 | I19: 340 | J19: =G19*2000+H19*1000+I19*250 -> 100000
C20: 16 | D20: 136 | E20: =C20*2000+D20*500 -> 100000 | G20: 6 | H20: 4 | I20: 336 | J20: =G20*2000+H20*1000+I20*250 -> 100000
C21: 17 | D21: 132 | E21: =C21*2000+D21*500 -> 100000 | G21: 7 | H21: 3 | I21: 332 | J21: =G21*2000+H21*1000+I21*250 -> 100000
C22: 18 | D22: 128 | E22: =C22*2000+D22*500 -> 100000 | G22: 8 | H22: 2 | I22: 328 | J22: =G22*2000+H22*1000+I22*250 -> 100000
C23: 19 | D23: 124 | E23: =C23*2000+D23*500 -> 100000 | G23: 9 | H23: 1 | I23: 324 | J23: =G23*2000+H23*1000+I23*250 -> 100000
C24: 20 | D24: 120 | E24: =C24*2000+D24*500 -> 100000 | G24: 10 | H24: 0 | I24: 320 | J24: =G24*2000+H24*1000+I24*250 -> 100000
C25: 21 | D25: 116 | E25: =C25*2000+D25*500 -> 100000 | H25: 21 | I25: 316 | J25: =G25*2000+H25*1000+I25*250 -> 100000
C26: 22 | D26: 112 | E26: =C26*2000+D26*500 -> 100000 | H26: 22 | I26: 312 | J26: =G26*2000+H26*1000+I26*250 -> 100000
C27: 23 | D27: 108 | E27: =C27*2000+D27*500 -> 100000 | H27: 23 | I27: 308 | J27: =G27*2000+H27*1000+I27*250 -> 100000
C28: 24 | D28: 104 | E28: =C28*2000+D28*500 -> 100000 | H28: 24 | I28: 304 | J28: =G28*2000+H28*1000+I28*250 -> 100000
C29: 25 | D29: 100 | E29: =C29*2000+D29*500 -> 100000 | H29: 25 | I29: 300 | J29: =G29*2000+H29*1000+I29*250 -> 100000
C30: 26 | D30: 96 | E30: =C30*2000+D30*500 -> 100000 | H30: 26 | I30: 296 | J30: =G30*2000+H30*1000+I30*250 -> 100000
C31: 27 | D31: 92 | E31: =C31*2000+D31*500 -> 100000 | H31: 27 | I31: 292 | J31: =G31*2000+H31*1000+I31*250 -> 100000
C32: 28 | D32: 88 | E32: =C32*2000+D32*500 -> 100000 | H32: 28 | I32: 288 | J32: =G32*2000+H32*1000+I32*250 -> 100000
C33: 29 | D33: 84 | E33: =C33*2000+D33*500 -> 100000 | H33: 29 | I33: 284 | J33: =G33*2000+H33*1000+I33*250 -> 100000
C34: 30 | D34: 80 | E34: =C34*2000+D34*500 -> 100000 | H34: 30 | I34: 280 | J34: =G34*2000+H34*1000+I34*250 -> 100000
D37: 100kg FORMULAE from ASHKAN for AF,EF and JF
C38: CASES of 200g | D38: 500g | E38: 200g | F38: 100kg | G38: Grams remaining
C39: 81 | D39: 8 | E39: 480 | F39: =D39*500+E39*200 -> 100000 | G39: =100000-F39 -> 0
C40: 83 | D40: 0 | E40: 498 | F40: =D40*500+E40*200 -> 99600 | G40: =100000-F40 -> 400
C41: 82 | D41: 3 | E41: 492 | F41: =D41*500+E41*200 -> 99900 | G41: =100000-F41 -> 100
C42: 81 | D42: 5 | E42: 486 | F42: =D42*500+E42*200 -> 99700 | G42: =100000-F42 -> 300
C43: =C42-1 -> 80 | D43: 8 | E43: =E42-6 -> 480 | F43: =D43*500+E43*200 -> 100000 | G43: =100000-F43 -> 0
C44: =C43-1 -> 79 | D44: 10 | E44: =E43-6 -> 474 | F44: =D44*500+E44*200 -> 99800 | G44: =100000-F44 -> 200
...

Sheet CM
A1: THH STOCK: | F1: 2026
F2: 46023 | I2: 46054 | L2: 46082 | O2: 46113 | R2: 46143 | U2: 46174 | X2: 46204 | AA2: 46235 | AD2: 46266 | AG2: 46296 | AJ2: 46327 | AM2: 46357
A3: Description | B3: Batch Numner | C3: Expiry Date | D3: Current STOCK | E3: Reorder point | F3: IN | G3: OUT | H3: STOCK | I3: IN | J3: OUT | K3: STOCK | L3: IN | M3: OUT | N3: STOCK | O3: IN | P3: OUT | Q3: STOCK | R3: IN | S3: OUT | T3: STOCK | U3: IN | V3: OUT | W3: STOCK | X3: IN | Y3: OUT | Z3: STOCK | AA3: IN | AB3: OUT | AC3: STOCK | AD3: IN | AE3: OUT | AF3: STOCK | AG3: IN | AH3: OUT | AI3: STOCK | AJ3: IN | AK3: OUT | AL3: STOCK | AM3: IN | AN3: OUT | AO3: STOCK
A4: Calm Mix 500g
A5: Herbal Horse & Pet | B5: 160220261HHPCM | C5: 16/02/2028 | D5: =LOOKUP(2,1/(F5:DI5<>""),F5:DI5) -> 28 | H5: =F5-G5 -> 0 | K5: =H5+I5-J5 -> 0 | L5: 28 | N5: =K5+L5-M5 -> 28 | Q5: =N5+O5-P5 -> 28 | T5: =Q5+R5-S5 -> 28 | W5: =T5+U5-V5 -> 28 | Z5: =W5+X5-Y5 -> 28 | AC5: =Z5+AA5-AB5 -> 28 | AF5: =AC5+AD5-AE5 -> 28 | AI5: =AF5+AG5-AH5 -> 28 | AL5: =AI5+AJ5-AK5 -> 28 | AO5: =AL5+AM5-AN5 -> 28
A6: Current STOCK | D6: =LOOKUP(2,1/(F6:DI6<>""),F6:DI6) -> 0 | H6: =F6-G6 -> 0 | K6: =H6+I6-J6 -> 0 | N6: =K6+L6-M6 -> 0 | Q6: =N6+O6-P6 -> 0 | T6: =Q6+R6-S6 -> 0 | W6: =T6+U6-V6 -> 0 | Z6: =W6+X6-Y6 -> 0 | AC6: =Z6+AA6-AB6 -> 0 | AF6: =AC6+AD6-AE6 -> 0 | AI6: =AF6+AG6-AH6 -> 0 | AL6: =AI6+AJ6-AK6 -> 0 | AO6: =AL6+AM6-AN6 -> 0
A7: =D21 -> 28 | D7: =LOOKUP(2,1/(F7:DI7<>""),F7:DI7) -> 0 | H7: =F7-G7 -> 0 | K7: =H7+I7-J7 -> 0 | N7: =K7+L7-M7 -> 0 | Q7: =N7+O7-P7 -> 0 | T7: =Q7+R7-S7 -> 0 | W7: =T7+U7-V7 -> 0 | Z7: =W7+X7-Y7 -> 0 | AC7: =Z7+AA7-AB7 -> 0 | AF7: =AC7+AD7-AE7 -> 0 | AI7: =AF7+AG7-AH7 -> 0 | AL7: =AI7+AJ7-AK7 -> 0 | AO7: =AL7+AM7-AN7 -> 0
D8: =LOOKUP(2,1/(F8:DI8<>""),F8:DI8) -> 0 | H8: =F8-G8 -> 0 | K8: =H8+I8-J8 -> 0 | N8: =K8+L8-M8 -> 0 | Q8: =N8+O8-P8 -> 0 | T8: =Q8+R8-S8 -> 0 | W8: =T8+U8-V8 -> 0 | Z8: =W8+X8-Y8 -> 0 | AC8: =Z8+AA8-AB8 -> 0 | AF8: =AC8+AD8-AE8 -> 0 | AI8: =AF8+AG8-AH8 -> 0 | AL8: =AI8+AJ8-AK8 -> 0 | AO8: =AL8+AM8-AN8 -> 0
D9: =LOOKUP(2,1/(F9:DI9<>""),F9:DI9) -> 0 | H9: =F9-G9 -> 0 | K9: =H9+I9-J9 -> 0 | N9: =K9+L9-M9 -> 0 | Q9: =N9+O9-P9 -> 0 | T9: =Q9+R9-S9 -> 0 | W9: =T9+U9-V9 -> 0 | Z9: =W9+X9-Y9 -> 0 | AC9: =Z9+AA9-AB9 -> 0 | AF9: =AC9+AD9-AE9 -> 0 | AI9: =AF9+AG9-AH9 -> 0 | AL9: =AI9+AJ9-AK9 -> 0 | AO9: =AL9+AM9-AN9 -> 0
D10: =LOOKUP(2,1/(F10:DI10<>""),F10:DI10) -> 0 | H10: =F10-G10 -> 0 | K10: =H10+I10-J10 -> 0 | N10: =K10+L10-M10 -> 0 | Q10: =N10+O10-P10 -> 0 | T10: =Q10+R10-S10 -> 0 | W10: =T10+U10-V10 -> 0 | Z10: =W10+X10-Y10 -> 0 | AC10: =Z10+AA10-AB10 -> 0 | AF10: =AC10+AD10-AE10 -> 0 | AI10: =AF10+AG10-AH10 -> 0 | AL10: =AI10+AJ10-AK10 -> 0 | AO10: =AL10+AM10-AN10 -> 0
D11: =LOOKUP(2,1/(F11:DI11<>""),F11:DI11) -> 0 | H11: =F11-G11 -> 0 | K11: =H11+I11-J11 -> 0 | N11: =K11+L11-M11 -> 0 | Q11: =N11+O11-P11 -> 0 | T11: =Q11+R11-S11 -> 0 | W11: =T11+U11-V11 -> 0 | Z11: =W11+X11-Y11 -> 0 | AC11: =Z11+AA11-AB11 -> 0 | AF11: =AC11+AD11-AE11 -> 0 | AI11: =AF11+AG11-AH11 -> 0 | AL11: =AI11+AJ11-AK11 -> 0 | AO11: =AL11+AM11-AN11 -> 0
D12: =LOOKUP(2,1/(F12:DI12<>""),F12:DI12) -> 0 | H12: =F12-G12 -> 0 | K12: =H12+I12-J12 -> 0 | N12: =K12+L12-M12 -> 0 | Q12: =N12+O12-P12 -> 0 | T12: =Q12+R12-S12 -> 0 | W12: =T12+U12-V12 -> 0 | Z12: =W12+X12-Y12 -> 0 | AC12: =Z12+AA12-AB12 -> 0 | AF12: =AC12+AD12-AE12 -> 0 | AI12: =AF12+AG12-AH12 -> 0 | AL12: =AI12+AJ12-AK12 -> 0 | AO12: =AL12+AM12-AN12 -> 0
D13: =LOOKUP(2,1/(F13:DI13<>""),F13:DI13) -> 0 | F13: 0 | G13: 0 | H13: =F13-G13 -> 0 | K13: =H13+I13-J13 -> 0 | N13: =K13+L13-M13 -> 0 | Q13: =N13+O13-P13 -> 0 | T13: =Q13+R13-S13 -> 0 | W13: =T13+U13-V13 -> 0 | Z13: =W13+X13-Y13 -> 0 | AC13: =Z13+AA13-AB13 -> 0 | AF13: =AC13+AD13-AE13 -> 0 | AI13: =AF13+AG13-AH13 -> 0 | AL13: =AI13+AJ13-AK13 -> 0 | AO13: =AL13+AM13-AN13 -> 0
D14: =LOOKUP(2,1/(F14:DI14<>""),F14:DI14) -> 0 | H14: =F14-G14 -> 0 | K14: =H14+I14-J14 -> 0 | N14: =K14+L14-M14 -> 0 | Q14: =N14+O14-P14 -> 0 | T14: =Q14+R14-S14 -> 0 | W14: =T14+U14-V14 -> 0 | Z14: =W14+X14-Y14 -> 0 | AC14: =Z14+AA14-AB14 -> 0 | AF14: =AC14+AD14-AE14 -> 0 | AI14: =AF14+AG14-AH14 -> 0 | AL14: =AI14+AJ14-AK14 -> 0 | AO14: =AL14+AM14-AN14 -> 0
D15: =LOOKUP(2,1/(F15:DI15<>""),F15:DI15) -> 0 | H15: =F15-G15 -> 0 | K15: =H15+I15-J15 -> 0 | N15: =K15+L15-M15 -> 0 | Q15: =N15+O15-P15 -> 0 | T15: =Q15+R15-S15 -> 0 | W15: =T15+U15-V15 -> 0 | Z15: =W15+X15-Y15 -> 0 | AC15: =Z15+AA15-AB15 -> 0 | AF15: =AC15+AD15-AE15 -> 0 | AI15: =AF15+AG15-AH15 -> 0 | AL15: =AI15+AJ15-AK15 -> 0 | AO15: =AL15+AM15-AN15 -> 0
D16: =LOOKUP(2,1/(F16:DI16<>""),F16:DI16) -> 0 | H16: =F16-G16 -> 0 | K16: =H16+I16-J16 -> 0 | N16: =K16+L16-M16 -> 0 | Q16: =N16+O16-P16 -> 0 | T16: =Q16+R16-S16 -> 0 | W16: =T16+U16-V16 -> 0 | Z16: =W16+X16-Y16 -> 0 | AC16: =Z16+AA16-AB16 -> 0 | AF16: =AC16+AD16-AE16 -> 0 | AI16: =AF16+AG16-AH16 -> 0 | AL16: =AI16+AJ16-AK16 -> 0 | AO16: =AL16+AM16-AN16 -> 0
D17: =LOOKUP(2,1/(F17:DI17<>""),F17:DI17) -> 0 | H17: =F17-G17 -> 0 | K17: =H17+I17-J17 -> 0 | N17: =K17+L17-M17 -> 0 | Q17: =N17+O17-P17 -> 0 | T17: =Q17+R17-S17 -> 0 | W17: =T17+U17-V17 -> 0 | Z17: =W17+X17-Y17 -> 0 | AC17: =Z17+AA17-AB17 -> 0 | AF17: =AC17+AD17-AE17 -> 0 | AI17: =AF17+AG17-AH17 -> 0 | AL17: =AI17+AJ17-AK17 -> 0 | AO17: =AL17+AM17-AN17 -> 0
D18: =LOOKUP(2,1/(F18:DI18<>""),F18:DI18) -> 0 | H18: =F18-G18 -> 0 | K18: =H18+I18-J18 -> 0 | N18: =K18+L18-M18 -> 0 | Q18: =N18+O18-P18 -> 0 | T18: =Q18+R18-S18 -> 0 | W18: =T18+U18-V18 -> 0 | Z18: =W18+X18-Y18 -> 0 | AC18: =Z18+AA18-AB18 -> 0 | AF18: =AC18+AD18-AE18 -> 0 | AI18: =AF18+AG18-AH18 -> 0 | AL18: =AI18+AJ18-AK18 -> 0 | AO18: =AL18+AM18-AN18 -> 0
D19: =LOOKUP(2,1/(F19:DI19<>""),F19:DI19) -> 0 | H19: =F19-G19 -> 0 | K19: =H19+I19-J19 -> 0 | N19: =K19+L19-M19 -> 0 | Q19: =N19+O19-P19 -> 0 | T19: =Q19+R19-S19 -> 0 | W19: =T19+U19-V19 -> 0 | Z19: =W19+X19-Y19 -> 0 | AC19: =Z19+AA19-AB19 -> 0 | AF19: =AC19+AD19-AE19 -> 0 | AI19: =AF19+AG19-AH19 -> 0 | AL19: =AI19+AJ19-AK19 -> 0 | AO19: =AL19+AM19-AN19 -> 0
D20: =LOOKUP(2,1/(F20:DI20<>""),F20:DI20) -> 0 | H20: =F20-G20 -> 0 | K20: =H20+I20-J20 -> 0 | N20: =K20+L20-M20 -> 0 | Q20: =N20+O20-P20 -> 0 | T20: =Q20+R20-S20 -> 0 | W20: =T20+U20-V20 -> 0 | Z20: =W20+X20-Y20 -> 0 | AC20: =Z20+AA20-AB20 -> 0 | AF20: =AC20+AD20-AE20 -> 0 | AI20: =AF20+AG20-AH20 -> 0 | AL20: =AI20+AJ20-AK20 -> 0 | AO20: =AL20+AM20-AN20 -> 0
D21: =SUM(D5:D20) -> 28 | H21: =F21-G21 -> 0 | K21: =H21+I21-J21 -> 0 | N21: =K21+L21-M21 -> 0 | Q21: =N21+O21-P21 -> 0 | T21: =Q21+R21-S21 -> 0 | W21: =T21+U21-V21 -> 0 | Z21: =W21+X21-Y21 -> 0 | AC21: =Z21+AA21-AB21 -> 0 | AF21: =AC21+AD21-AE21 -> 0 | AI21: =AF21+AG21-AH21 -> 0 | AL21: =AI21+AJ21-AK21 -> 0 | AO21: =AL21+AM21-AN21 -> 0
A22: Calm Mix 2kg
A23: Herbal Horse & Pet | B23: 171120251HHPCM | C23: 11/2027 | D23: =LOOKUP(2,1/(F23:DI23<>""),F23:DI23) -> 1 | F23: 16+F23:R23 | H23: =F23-G23 -> #VALUE! | K23: 0 | L23: 1 | N23: =K23+L23-M23 -> 1 | Q23: =N23+O23-P23 -> 1 | T23: =Q23+R23-S23 -> 1 | W23: =T23+U23-V23 -> 1 | Z23: =W23+X23-Y23 -> 1 | AC23: =Z23+AA23-AB23 -> 1 | AF23: =AC23+AD23-AE23 -> 1 | AI23: =AF23+AG23-AH23 -> 1 | AL23: =AI23+AJ23-AK23 -> 1 | AO23: =AL23+AM23-AN23 -> 1
A24: Current STOCK | D24: =LOOKUP(2,1/(F24:DI24<>""),F24:DI24) -> 0 | H24: =F24-G24 -> 0 | K24: =H24+I24-J24 -> 0 | N24: =K24+L24-M24 -> 0 | Q24: =N24+O24-P24 -> 0 | T24: =Q24+R24-S24 -> 0 | W24: =T24+U24-V24 -> 0 | Z24: =W24+X24-Y24 -> 0 | AC24: =Z24+AA24-AB24 -> 0 | AF24: =AC24+AD24-AE24 -> 0 | AI24: =AF24+AG24-AH24 -> 0 | AL24: =AI24+AJ24-AK24 -> 0 | AO24: =AL24+AM24-AN24 -> 0
A25: =D39 -> 1 | D25: =LOOKUP(2,1/(F25:DI25<>""),F25:DI25) -> 0 | H25: =F25-G25 -> 0 | K25: =H25+I25-J25 -> 0 | N25: =K25+L25-M25 -> 0 | Q25: =N25+O25-P25 -> 0 | T25: =Q25+R25-S25 -> 0 | W25: =T25+U25-V25 -> 0 | Z25: =W25+X25-Y25 -> 0 | AC25: =Z25+AA25-AB25 -> 0 | AF25: =AC25+AD25-AE25 -> 0 | AI25: =AF25+AG25-AH25 -> 0 | AL25: =AI25+AJ25-AK25 -> 0 | AO25: =AL25+AM25-AN25 -> 0
D26: =LOOKUP(2,1/(F26:DI26<>""),F26:DI26) -> 0 | H26: =F26-G26 -> 0 | K26: =H26+I26-J26 -> 0 | N26: =K26+L26-M26 -> 0 | Q26: =N26+O26-P26 -> 0 | T26: =Q26+R26-S26 -> 0 | W26: =T26+U26-V26 -> 0 | Z26: =W26+X26-Y26 -> 0 | AC26: =Z26+AA26-AB26 -> 0 | AF26: =AC26+AD26-AE26 -> 0 | AI26: =AF26+AG26-AH26 -> 0 | AL26: =AI26+AJ26-AK26 -> 0 | AO26: =AL26+AM26-AN26 -> 0
D27: =LOOKUP(2,1/(F27:DI27<>""),F27:DI27) -> 0 | H27: =F27-G27 -> 0 | K27: =H27+I27-J27 -> 0 | N27: =K27+L27-M27 -> 0 | Q27: =N27+O27-P27 -> 0 | T27: =Q27+R27-S27 -> 0 | W27: =T27+U27-V27 -> 0 | Z27: =W27+X27-Y27 -> 0 | AC27: =Z27+AA27-AB27 -> 0 | AF27: =AC27+AD27-AE27 -> 0 | AI27: =AF27+AG27-AH27 -> 0 | AL27: =AI27+AJ27-AK27 -> 0 | AO27: =AL27+AM27-AN27 -> 0
D28: =LOOKUP(2,1/(F28:DI28<>""),F28:DI28) -> 0 | H28: =F28-G28 -> 0 | K28: =H28+I28-J28 -> 0 | N28: =K28+L28-M28 -> 0 | Q28: =N28+O28-P28 -> 0 | T28: =Q28+R28-S28 -> 0 | W28: =T28+U28-V28 -> 0 | Z28: =W28+X28-Y28 -> 0 | AC28: =Z28+AA28-AB28 -> 0 | AF28: =AC28+AD28-AE28 -> 0 | AI28: =AF28+AG28-AH28 -> 0 | AL28: =AI28+AJ28-AK28 -> 0 | AO28: =AL28+AM28-AN28 -> 0
D29: =LOOKUP(2,1/(F29:DI29<>""),F29:DI29) -> 0 | H29: =F29-G29 -> 0 | K29: =H29+I29-J29 -> 0 | N29: =K29+L29-M29 -> 0 | Q29: =N29+O29-P29 -> 0 | T29: =Q29+R29-S29 -> 0 | W29: =T29+U29-V29 -> 0 | Z29: =W29+X29-Y29 -> 0 | AC29: =Z29+AA29-AB29 -> 0 | AF29: =AC29+AD29-AE29 -> 0 | AI29: =AF29+AG29-AH29 -> 0 | AL29: =AI29+AJ29-AK29 -> 0 | AO29: =AL29+AM29-AN29 -> 0
D30: =LOOKUP(2,1/(F30:DI30<>""),F30:DI30) -> 0 | H30: =F30-G30 -> 0 | K30: =H30+I30-J30 -> 0 | N30: =K30+L30-M30 -> 0 | Q30: =N30+O30-P30 -> 0 | T30: =Q30+R30-S30 -> 0 | W30: =T30+U30-V30 -> 0 | Z30: =W30+X30-Y30 -> 0 | AC30: =Z30+AA30-AB30 -> 0 | AF30: =AC30+AD30-AE30 -> 0 | AI30: =AF30+AG30-AH30 -> 0 | AL30: =AI30+AJ30-AK30 -> 0 | AO30: =AL30+AM30-AN30 -> 0
D31: =LOOKUP(2,1/(F31:DI31<>""),F31:DI31) -> 0 | H31: =F31-G31 -> 0 | K31: =H31+I31-J31 -> 0 | N31: =K31+L31-M31 -> 0 | Q31: =N31+O31-P31 -> 0 | T31: =Q31+R31-S31 -> 0 | W31: =T31+U31-V31 -> 0 | Z31: =W31+X31-Y31 -> 0 | AC31: =Z31+AA31-AB31 -> 0 | AF31: =AC31+AD31-AE31 -> 0 | AI31: =AF31+AG31-AH31 -> 0 | AL31: =AI31+AJ31-AK31 -> 0 | AO31: =AL31+AM31-AN31 -> 0
D32: =LOOKUP(2,1/(F32:DI32<>""),F32:DI32) -> 0 | H32: =F32-G32 -> 0 | K32: =H32+I32-J32 -> 0 | N32: =K32+L32-M32 -> 0 | Q32: =N32+O32-P32 -> 0 | T32: =Q32+R32-S32 -> 0 | W32: =T32+U32-V32 -> 0 | Z32: =W32+X32-Y32 -> 0 | AC32: =Z32+AA32-AB32 -> 0 | AF32: =AC32+AD32-AE32 -> 0 | AI32: =AF32+AG32-AH32 -> 0 | AL32: =AI32+AJ32-AK32 -> 0 | AO32: =AL32+AM32-AN32 -> 0
D33: =LOOKUP(2,1/(F33:DI33<>""),F33:DI33) -> 0 | H33: =F33-G33 -> 0 | K33: =H33+I33-J33 -> 0 | N33: =K33+L33-M33 -> 0 | Q33: =N33+O33-P33 -> 0 | T33: =Q33+R33-S33 -> 0 | W33: =T33+U33-V33 -> 0 | Z33: =W33+X33-Y33 -> 0 | AC33: =Z33+AA33-AB33 -> 0 | AF33: =AC33+AD33-AE33 -> 0 | AI33: =AF33+AG33-AH33 -> 0 | AL33: =AI33+AJ33-AK33 -> 0 | AO33: =AL33+AM33-AN33 -> 0
D34: =LOOKUP(2,1/(F34:DI34<>""),F34:DI34) -> 0 | H34: =F34-G34 -> 0 | K34: =H34+I34-J34 -> 0 | N34: =K34+L34-M34 -> 0 | Q34: =N34+O34-P34 -> 0 | T34: =Q34+R34-S34 -> 0 | W34: =T34+U34-V34 -> 0 | Z34: =W34+X34-Y34 -> 0 | AC34: =Z34+AA34-AB34 -> 0 | AF34: =AC34+AD34-AE34 -> 0 | AI34: =AF34+AG34-AH34 -> 0 | AL34: =AI34+AJ34-AK34 -> 0 | AO34: =AL34+AM34-AN34 -> 0
D35: =LOOKUP(2,1/(F35:DI35<>""),F35:DI35) -> 0 | H35: =F35-G35 -> 0 | K35: =H35+I35-J35 -> 0 | N35: =K35+L35-M35 -> 0 | Q35: =N35+O35-P35 -> 0 | T35: =Q35+R35-S35 -> 0 | W35: =T35+U35-V35 -> 0 | Z35: =W35+X35-Y35 -> 0 | AC35: =Z35+AA35-AB35 -> 0 | AF35: =AC35+AD35-AE35 -> 0 | AI35: =AF35+AG35-AH35 -> 0 | AL35: =AI35+AJ35-AK35 -> 0 | AO35: =AL35+AM35-AN35 -> 0
D36: =LOOKUP(2,1/(F36:DI36<>""),F36:DI36) -> 0 | H36: =F36-G36 -> 0 | K36: =H36+I36-J36 -> 0 | N36: =K36+L36-M36 -> 0 | Q36: =N36+O36-P36 -> 0 | T36: =Q36+R36-S36 -> 0 | W36: =T36+U36-V36 -> 0 | Z36: =W36+X36-Y36 -> 0 | AC36: =Z36+AA36-AB36 -> 0 | AF36: =AC36+AD36-AE36 -> 0 | AI36: =AF36+AG36-AH36 -> 0 | AL36: =AI36+AJ36-AK36 -> 0 | AO36: =AL36+AM36-AN36 -> 0
D37: =LOOKUP(2,1/(F37:DI37<>""),F37:DI37) -> 0 | H37: =F37-G37 -> 0 | K37: =H37+I37-J37 -> 0 | N37: =K37+L37-M37 -> 0 | Q37: =N37+O37-P37 -> 0 | T37: =Q37+R37-S37 -> 0 | W37: =T37+U37-V37 -> 0 | Z37: =W37+X37-Y37 -> 0 | AC37: =Z37+AA37-AB37 -> 0 | AF37: =AC37+AD37-AE37 -> 0 | AI37: =AF37+AG37-AH37 -> 0 | AL37: =AI37+AJ37-AK37 -> 0 | AO37: =AL37+AM37-AN37 -> 0
D38: =LOOKUP(2,1/(F38:DI38<>""),F38:DI38) -> 0 | H38: =F38-G38 -> 0 | K38: =H38+I38-J38 -> 0 | N38: =K38+L38-M38 -> 0 | Q38: =N38+O38-P38 -> 0 | T38: =Q38+R38-S38 -> 0 | W38: =T38+U38-V38 -> 0 | Z38: =W38+X38-Y38 -> 0 | AC38: =Z38+AA38-AB38 -> 0 | AF38: =AC38+AD38-AE38 -> 0 | AI38: =AF38+AG38-AH38 -> 0 | AL38: =AI38+AJ38-AK38 -> 0 | AO38: =AL38+AM38-AN38 -> 0
D39: =SUM(D23:D38) -> 1 | H39: =F39-G39 -> 0 | K39: =H39+I39-J39 -> 0 | N39: =K39+L39-M39 -> 0 | Q39: =N39+O39-P39 -> 0 | T39: =Q39+R39-S39 -> 0 | W39: =T39+U39-V39 -> 0 | Z39: =W39+X39-Y39 -> 0 | AC39: =Z39+AA39-AB39 -> 0 | AF39: =AC39+AD39-AE39 -> 0 | AI39: =AF39+AG39-AH39 -> 0 | AL39: =AI39+AJ39-AK39 -> 0 | AO39: =AL39+AM39-AN39 -> 0
A43: NGL STOCK:
...

Sheet DM
A1: THH STOCK: | F1: 2026
F2: 46023 | I2: 46054 | L2: 46082 | O2: 46113 | R2: 46143 | U2: 46174 | X2: 46204 | AA2: 46235 | AD2: 46266 | AG2: 46296 | AJ2: 46327 | AM2: 46357
A3: Description | B3: Batch Numner | C3: Expiry Date | D3: Current STOCK | E3: Reorder point | F3: IN | G3: OUT | H3: STOCK | I3: IN | J3: OUT | K3: STOCK | L3: IN | M3: OUT | N3: STOCK | O3: IN | P3: OUT | Q3: STOCK | R3: IN | S3: OUT | T3: STOCK | U3: IN | V3: OUT | W3: STOCK | X3: IN | Y3: OUT | Z3: STOCK | AA3: IN | AB3: OUT | AC3: STOCK | AD3: IN | AE3: OUT | AF3: STOCK | AG3: IN | AH3: OUT | AI3: STOCK | AJ3: IN | AK3: OUT | AL3: STOCK | AM3: IN | AN3: OUT | AO3: STOCK
A4: Digestion Mix 500g
A5: Herbal Horse & Pet | B5: 180320261HHPDM | C5: 18/03/2028 | D5: =LOOKUP(2,1/(F5:DI5<>""),F5:DI5) -> 29 | F5: 0 | H5: =F5-G5 -> 0 | K5: =H5+I5-J5 -> 0 | L5: 29 | N5: =K5+L5-M5 -> 29 | Q5: =N5+O5-P5 -> 29 | T5: =Q5+R5-S5 -> 29 | W5: =T5+U5-V5 -> 29 | Z5: =W5+X5-Y5 -> 29 | AC5: =Z5+AA5-AB5 -> 29 | AF5: =AC5+AD5-AE5 -> 29 | AI5: =AF5+AG5-AH5 -> 29 | AL5: =AI5+AJ5-AK5 -> 29 | AO5: =AL5+AM5-AN5 -> 29 | AR5: =AO5+AP5-AQ5 -> 29 | AU5: =AR5+AS5-AT5 -> 29 | AX5: =AU5+AV5-AW5 -> 29 | BA5: =AX5+AY5-AZ5 -> 29 | BD5: =BA5+BB5-BC5 -> 29 | BG5: =BD5+BE5-BF5 -> 29 | BJ5: =BG5+BH5-BI5 -> 29 | BM5: =BJ5+BK5-BL5 -> 29 | BP5: =BM5+BN5-BO5 -> 29 | BS5: =BP5+BQ5-BR5 -> 29 | BV5: =BS5+BT5-BU5 -> 29 | BY5: =BV5+BW5-BX5 -> 29 | CB5: =BY5+BZ5-CA5 -> 29 | CE5: =CB5+CC5-CD5 -> 29 | CH5: =CE5+CF5-CG5 -> 29 | CK5: =CH5+CI5-CJ5 -> 29 | CN5: =CK5+CL5-CM5 -> 29 | CQ5: =CN5+CO5-CP5 -> 29 | CT5: =CQ5+CR5-CS5 -> 29 | CW5: =CT5+CU5-CV5 -> 29 | CZ5: =CW5+CX5-CY5 -> 29 | DC5: =CZ5+DA5-DB5 -> 29 | DF5: =DC5+DD5-DE5 -> 29 | DI5: =DF5+DG5-DH5 -> 29
A6: Current STOCK | D6: =LOOKUP(2,1/(F6:DI6<>""),F6:DI6) -> 0 | H6: =F6-G6 -> 0 | K6: =H6+I6-J6 -> 0 | N6: =K6+L6-M6 -> 0 | Q6: =N6+O6-P6 -> 0 | T6: =Q6+R6-S6 -> 0 | W6: =T6+U6-V6 -> 0 | Z6: =W6+X6-Y6 -> 0 | AC6: =Z6+AA6-AB6 -> 0 | AF6: =AC6+AD6-AE6 -> 0 | AI6: =AF6+AG6-AH6 -> 0 | AL6: =AI6+AJ6-AK6 -> 0 | AO6: =AL6+AM6-AN6 -> 0 | AR6: =AO6+AP6-AQ6 -> 0 | AU6: =AR6+AS6-AT6 -> 0 | AX6: =AU6+AV6-AW6 -> 0 | BA6: =AX6+AY6-AZ6 -> 0 | BD6: =BA6+BB6-BC6 -> 0 | BG6: =BD6+BE6-BF6 -> 0 | BJ6: =BG6+BH6-BI6 -> 0 | BM6: =BJ6+BK6-BL6 -> 0 | BP6: =BM6+BN6-BO6 -> 0 | BS6: =BP6+BQ6-BR6 -> 0 | BV6: =BS6+BT6-BU6 -> 0 | BY6: =BV6+BW6-BX6 -> 0 | CB6: =BY6+BZ6-CA6 -> 0 | CE6: =CB6+CC6-CD6 -> 0 | CH6: =CE6+CF6-CG6 -> 0 | CK6: =CH6+CI6-CJ6 -> 0 | CN6: =CK6+CL6-CM6 -> 0 | CQ6: =CN6+CO6-CP6 -> 0 | CT6: =CQ6+CR6-CS6 -> 0 | CW6: =CT6+CU6-CV6 -> 0 | CZ6: =CW6+CX6-CY6 -> 0 | DC6: =CZ6+DA6-DB6 -> 0 | DF6: =DC6+DD6-DE6 -> 0 | DI6: =DF6+DG6-DH6 -> 0
A7: =D21 -> 29 | D7: =LOOKUP(2,1/(F7:DI7<>""),F7:DI7) -> 0 | H7: =F7-G7 -> 0 | K7: =H7+I7-J7 -> 0 | N7: =K7+L7-M7 -> 0 | Q7: =N7+O7-P7 -> 0 | T7: =Q7+R7-S7 -> 0 | W7: =T7+U7-V7 -> 0 | Z7: =W7+X7-Y7 -> 0 | AC7: =Z7+AA7-AB7 -> 0 | AF7: =AC7+AD7-AE7 -> 0 | AI7: =AF7+AG7-AH7 -> 0 | AL7: =AI7+AJ7-AK7 -> 0 | AO7: =AL7+AM7-AN7 -> 0 | AR7: =AO7+AP7-AQ7 -> 0 | AU7: =AR7+AS7-AT7 -> 0 | AX7: =AU7+AV7-AW7 -> 0 | BA7: =AX7+AY7-AZ7 -> 0 | BD7: =BA7+BB7-BC7 -> 0 | BG7: =BD7+BE7-BF7 -> 0 | BJ7: =BG7+BH7-BI7 -> 0 | BM7: =BJ7+BK7-BL7 -> 0 | BP7: =BM7+BN7-BO7 -> 0 | BS7: =BP7+BQ7-BR7 -> 0 | BV7: =BS7+BT7-BU7 -> 0 | BY7: =BV7+BW7-BX7 -> 0 | CB7: =BY7+BZ7-CA7 -> 0 | CE7: =CB7+CC7-CD7 -> 0 | CH7: =CE7+CF7-CG7 -> 0 | CK7: =CH7+CI7-CJ7 -> 0 | CN7: =CK7+CL7-CM7 -> 0 | CQ7: =CN7+CO7-CP7 -> 0 | CT7: =CQ7+CR7-CS7 -> 0 | CW7: =CT7+CU7-CV7 -> 0 | CZ7: =CW7+CX7-CY7 -> 0 | DC7: =CZ7+DA7-DB7 -> 0 | DF7: =DC7+DD7-DE7 -> 0 | DI7: =DF7+DG7-DH7 -> 0
D8: =LOOKUP(2,1/(F8:DI8<>""),F8:DI8) -> 0 | H8: =F8-G8 -> 0 | K8: =H8+I8-J8 -> 0 | N8: =K8+L8-M8 -> 0 | Q8: =N8+O8-P8 -> 0 | T8: =Q8+R8-S8 -> 0 | W8: =T8+U8-V8 -> 0 | Z8: =W8+X8-Y8 -> 0 | AC8: =Z8+AA8-AB8 -> 0 | AF8: =AC8+AD8-AE8 -> 0 | AI8: =AF8+AG8-AH8 -> 0 | AL8: =AI8+AJ8-AK8 -> 0 | AO8: =AL8+AM8-AN8 -> 0 | AR8: =AO8+AP8-AQ8 -> 0 | AU8: =AR8+AS8-AT8 -> 0 | AX8: =AU8+AV8-AW8 -> 0 | BA8: =AX8+AY8-AZ8 -> 0 | BD8: =BA8+BB8-BC8 -> 0 | BG8: =BD8+BE8-BF8 -> 0 | BJ8: =BG8+BH8-BI8 -> 0 | BM8: =BJ8+BK8-BL8 -> 0 | BP8: =BM8+BN8-BO8 -> 0 | BS8: =BP8+BQ8-BR8 -> 0 | BV8: =BS8+BT8-BU8 -> 0 | BY8: =BV8+BW8-BX8 -> 0 | CB8: =BY8+BZ8-CA8 -> 0 | CE8: =CB8+CC8-CD8 -> 0 | CH8: =CE8+CF8-CG8 -> 0 | CK8: =CH8+CI8-CJ8 -> 0 | CN8: =CK8+CL8-CM8 -> 0 | CQ8: =CN8+CO8-CP8 -> 0 | CT8: =CQ8+CR8-CS8 -> 0 | CW8: =CT8+CU8-CV8 -> 0 | CZ8: =CW8+CX8-CY8 -> 0 | DC8: =CZ8+DA8-DB8 -> 0 | DF8: =DC8+DD8-DE8 -> 0 | DI8: =DF8+DG8-DH8 -> 0
D9: =LOOKUP(2,1/(F9:DI9<>""),F9:DI9) -> 0 | H9: =F9-G9 -> 0 | K9: =H9+I9-J9 -> 0 | N9: =K9+L9-M9 -> 0 | Q9: =N9+O9-P9 -> 0 | T9: =Q9+R9-S9 -> 0 | W9: =T9+U9-V9 -> 0 | Z9: =W9+X9-Y9 -> 0 | AC9: =Z9+AA9-AB9 -> 0 | AF9: =AC9+AD9-AE9 -> 0 | AI9: =AF9+AG9-AH9 -> 0 | AL9: =AI9+AJ9-AK9 -> 0 | AO9: =AL9+AM9-AN9 -> 0 | AR9: =AO9+AP9-AQ9 -> 0 | AU9: =AR9+AS9-AT9 -> 0 | AX9: =AU9+AV9-AW9 -> 0 | BA9: =AX9+AY9-AZ9 -> 0 | BD9: =BA9+BB9-BC9 -> 0 | BG9: =BD9+BE9-BF9 -> 0 | BJ9: =BG9+BH9-BI9 -> 0 | BM9: =BJ9+BK9-BL9 -> 0 | BP9: =BM9+BN9-BO9 -> 0 | BS9: =BP9+BQ9-BR9 -> 0 | BV9: =BS9+BT9-BU9 -> 0 | BY9: =BV9+BW9-BX9 -> 0 | CB9: =BY9+BZ9-CA9 -> 0 | CE9: =CB9+CC9-CD9 -> 0 | CH9: =CE9+CF9-CG9 -> 0 | CK9: =CH9+CI9-CJ9 -> 0 | CN9: =CK9+CL9-CM9 -> 0 | CQ9: =CN9+CO9-CP9 -> 0 | CT9: =CQ9+CR9-CS9 -> 0 | CW9: =CT9+CU9-CV9 -> 0 | CZ9: =CW9+CX9-CY9 -> 0 | DC9: =CZ9+DA9-DB9 -> 0 | DF9: =DC9+DD9-DE9 -> 0 | DI9: =DF9+DG9-DH9 -> 0
D10: =LOOKUP(2,1/(F10:DI10<>""),F10:DI10) -> 0 | H10: =F10-G10 -> 0 | K10: =H10+I10-J10 -> 0 | N10: =K10+L10-M10 -> 0 | Q10: =N10+O10-P10 -> 0 | T10: =Q10+R10-S10 -> 0 | W10: =T10+U10-V10 -> 0 | Z10: =W10+X10-Y10 -> 0 | AC10: =Z10+AA10-AB10 -> 0 | AF10: =AC10+AD10-AE10 -> 0 | AI10: =AF10+AG10-AH10 -> 0 | AL10: =AI10+AJ10-AK10 -> 0 | AO10: =AL10+AM10-AN10 -> 0 | AR10: =AO10+AP10-AQ10 -> 0 | AU10: =AR10+AS10-AT10 -> 0 | AX10: =AU10+AV10-AW10 -> 0 | BA10: =AX10+AY10-AZ10 -> 0 | BD10: =BA10+BB10-BC10 -> 0 | BG10: =BD10+BE10-BF10 -> 0 | BJ10: =BG10+BH10-BI10 -> 0 | BM10: =BJ10+BK10-BL10 -> 0 | BP10: =BM10+BN10-BO10 -> 0 | BS10: =BP10+BQ10-BR10 -> 0 | BV10: =BS10+BT10-BU10 -> 0 | BY10: =BV10+BW10-BX10 -> 0 | CB10: =BY10+BZ10-CA10 -> 0 | CE10: =CB10+CC10-CD10 -> 0 | CH10: =CE10+CF10-CG10 -> 0 | CK10: =CH10+CI10-CJ10 -> 0 | CN10: =CK10+CL10-CM10 -> 0 | CQ10: =CN10+CO10-CP10 -> 0 | CT10: =CQ10+CR10-CS10 -> 0 | CW10: =CT10+CU10-CV10 -> 0 | CZ10: =CW10+CX10-CY10 -> 0 | DC10: =CZ10+DA10-DB10 -> 0 | DF10: =DC10+DD10-DE10 -> 0 | DI10: =DF10+DG10-DH10 -> 0
D11: =LOOKUP(2,1/(F11:DI11<>""),F11:DI11) -> 0 | H11: =F11-G11 -> 0 | K11: =H11+I11-J11 -> 0 | N11: =K11+L11-M11 -> 0 | Q11: =N11+O11-P11 -> 0 | T11: =Q11+R11-S11 -> 0 | W11: =T11+U11-V11 -> 0 | Z11: =W11+X11-Y11 -> 0 | AC11: =Z11+AA11-AB11 -> 0 | AF11: =AC11+AD11-AE11 -> 0 | AI11: =AF11+AG11-AH11 -> 0 | AL11: =AI11+AJ11-AK11 -> 0 | AO11: =AL11+AM11-AN11 -> 0 | AR11: =AO11+AP11-AQ11 -> 0 | AU11: =AR11+AS11-AT11 -> 0 | AX11: =AU11+AV11-AW11 -> 0 | BA11: =AX11+AY11-AZ11 -> 0 | BD11: =BA11+BB11-BC11 -> 0 | BG11: =BD11+BE11-BF11 -> 0 | BJ11: =BG11+BH11-BI11 -> 0 | BM11: =BJ11+BK11-BL11 -> 0 | BP11: =BM11+BN11-BO11 -> 0 | BS11: =BP11+BQ11-BR11 -> 0 | BV11: =BS11+BT11-BU11 -> 0 | BY11: =BV11+BW11-BX11 -> 0 | CB11: =BY11+BZ11-CA11 -> 0 | CE11: =CB11+CC11-CD11 -> 0 | CH11: =CE11+CF11-CG11 -> 0 | CK11: =CH11+CI11-CJ11 -> 0 | CN11: =CK11+CL11-CM11 -> 0 | CQ11: =CN11+CO11-CP11 -> 0 | CT11: =CQ11+CR11-CS11 -> 0 | CW11: =CT11+CU11-CV11 -> 0 | CZ11: =CW11+CX11-CY11 -> 0 | DC11: =CZ11+DA11-DB11 -> 0 | DF11: =DC11+DD11-DE11 -> 0 | DI11: =DF11+DG11-DH11 -> 0
D12: =LOOKUP(2,1/(F12:DI12<>""),F12:DI12) -> 0 | H12: =F12-G12 -> 0 | K12: =H12+I12-J12 -> 0 | N12: =K12+L12-M12 -> 0 | Q12: =N12+O12-P12 -> 0 | T12: =Q12+R12-S12 -> 0 | W12: =T12+U12-V12 -> 0 | Z12: =W12+X12-Y12 -> 0 | AC12: =Z12+AA12-AB12 -> 0 | AF12: =AC12+AD12-AE12 -> 0 | AI12: =AF12+AG12-AH12 -> 0 | AL12: =AI12+AJ12-AK12 -> 0 | AO12: =AL12+AM12-AN12 -> 0 | AR12: =AO12+AP12-AQ12 -> 0 | AU12: =AR12+AS12-AT12 -> 0 | AX12: =AU12+AV12-AW12 -> 0 | BA12: =AX12+AY12-AZ12 -> 0 | BD12: =BA12+BB12-BC12 -> 0 | BG12: =BD12+BE12-BF12 -> 0 | BJ12: =BG12+BH12-BI12 -> 0 | BM12: =BJ12+BK12-BL12 -> 0 | BP12: =BM12+BN12-BO12 -> 0 | BS12: =BP12+BQ12-BR12 -> 0 | BV12: =BS12+BT12-BU12 -> 0 | BY12: =BV12+BW12-BX12 -> 0 | CB12: =BY12+BZ12-CA12 -> 0 | CE12: =CB12+CC12-CD12 -> 0 | CH12: =CE12+CF12-CG12 -> 0 | CK12: =CH12+CI12-CJ12 -> 0 | CN12: =CK12+CL12-CM12 -> 0 | CQ12: =CN12+CO12-CP12 -> 0 | CT12: =CQ12+CR12-CS12 -> 0 | CW12: =CT12+CU12-CV12 -> 0 | CZ12: =CW12+CX12-CY12 -> 0 | DC12: =CZ12+DA12-DB12 -> 0 | DF12: =DC12+DD12-DE12 -> 0 | DI12: =DF12+DG12-DH12 -> 0
D13: =LOOKUP(2,1/(F13:DI13<>""),F13:DI13) -> 0 | F13: 0 | G13: 0 | H13: =F13-G13 -> 0 | K13: =H13+I13-J13 -> 0 | N13: =K13+L13-M13 -> 0 | Q13: =N13+O13-P13 -> 0 | T13: =Q13+R13-S13 -> 0 | W13: =T13+U13-V13 -> 0 | Z13: =W13+X13-Y13 -> 0 | AC13: =Z13+AA13-AB13 -> 0 | AF13: =AC13+AD13-AE13 -> 0 | AI13: =AF13+AG13-AH13 -> 0 | AL13: =AI13+AJ13-AK13 -> 0 | AO13: =AL13+AM13-AN13 -> 0 | AR13: =AO13+AP13-AQ13 -> 0 | AU13: =AR13+AS13-AT13 -> 0 | AX13: =AU13+AV13-AW13 -> 0 | BA13: =AX13+AY13-AZ13 -> 0 | BD13: =BA13+BB13-BC13 -> 0 | BG13: =BD13+BE13-BF13 -> 0 | BJ13: =BG13+BH13-BI13 -> 0 | BM13: =BJ13+BK13-BL13 -> 0 | BP13: =BM13+BN13-BO13 -> 0 | BS13: =BP13+BQ13-BR13 -> 0 | BV13: =BS13+BT13-BU13 -> 0 | BY13: =BV13+BW13-BX13 -> 0 | CB13: =BY13+BZ13-CA13 -> 0 | CE13: =CB13+CC13-CD13 -> 0 | CH13: =CE13+CF13-CG13 -> 0 | CK13: =CH13+CI13-CJ13 -> 0 | CN13: =CK13+CL13-CM13 -> 0 | CQ13: =CN13+CO13-CP13 -> 0 | CT13: =CQ13+CR13-CS13 -> 0 | CW13: =CT13+CU13-CV13 -> 0 | CZ13: =CW13+CX13-CY13 -> 0 | DC13: =CZ13+DA13-DB13 -> 0 | DF13: =DC13+DD13-DE13 -> 0 | DI13: =DF13+DG13-DH13 -> 0
D14: =LOOKUP(2,1/(F14:DI14<>""),F14:DI14) -> 0 | H14: =F14-G14 -> 0 | K14: =H14+I14-J14 -> 0 | N14: =K14+L14-M14 -> 0 | Q14: =N14+O14-P14 -> 0 | T14: =Q14+R14-S14 -> 0 | W14: =T14+U14-V14 -> 0 | Z14: =W14+X14-Y14 -> 0 | AC14: =Z14+AA14-AB14 -> 0 | AF14: =AC14+AD14-AE14 -> 0 | AI14: =AF14+AG14-AH14 -> 0 | AL14: =AI14+AJ14-AK14 -> 0 | AO14: =AL14+AM14-AN14 -> 0 | AR14: =AO14+AP14-AQ14 -> 0 | AU14: =AR14+AS14-AT14 -> 0 | AX14: =AU14+AV14-AW14 -> 0 | BA14: =AX14+AY14-AZ14 -> 0 | BD14: =BA14+BB14-BC14 -> 0 | BG14: =BD14+BE14-BF14 -> 0 | BJ14: =BG14+BH14-BI14 -> 0 | BM14: =BJ14+BK14-BL14 -> 0 | BP14: =BM14+BN14-BO14 -> 0 | BS14: =BP14+BQ14-BR14 -> 0 | BV14: =BS14+BT14-BU14 -> 0 | BY14: =BV14+BW14-BX14 -> 0 | CB14: =BY14+BZ14-CA14 -> 0 | CE14: =CB14+CC14-CD14 -> 0 | CH14: =CE14+CF14-CG14 -> 0 | CK14: =CH14+CI14-CJ14 -> 0 | CN14: =CK14+CL14-CM14 -> 0 | CQ14: =CN14+CO14-CP14 -> 0 | CT14: =CQ14+CR14-CS14 -> 0 | CW14: =CT14+CU14-CV14 -> 0 | CZ14: =CW14+CX14-CY14 -> 0 | DC14: =CZ14+DA14-DB14 -> 0 | DF14: =DC14+DD14-DE14 -> 0 | DI14: =DF14+DG14-DH14 -> 0
D15: =LOOKUP(2,1/(F15:DI15<>""),F15:DI15) -> 0 | H15: =F15-G15 -> 0 | K15: =H15+I15-J15 -> 0 | N15: =K15+L15-M15 -> 0 | Q15: =N15+O15-P15 -> 0 | T15: =Q15+R15-S15 -> 0 | W15: =T15+U15-V15 -> 0 | Z15: =W15+X15-Y15 -> 0 | AC15: =Z15+AA15-AB15 -> 0 | AF15: =AC15+AD15-AE15 -> 0 | AI15: =AF15+AG15-AH15 -> 0 | AL15: =AI15+AJ15-AK15 -> 0 | AO15: =AL15+AM15-AN15 -> 0 | AR15: =AO15+AP15-AQ15 -> 0 | AU15: =AR15+AS15-AT15 -> 0 | AX15: =AU15+AV15-AW15 -> 0 | BA15: =AX15+AY15-AZ15 -> 0 | BD15: =BA15+BB15-BC15 -> 0 | BG15: =BD15+BE15-BF15 -> 0 | BJ15: =BG15+BH15-BI15 -> 0 | BM15: =BJ15+BK15-BL15 -> 0 | BP15: =BM15+BN15-BO15 -> 0 | BS15: =BP15+BQ15-BR15 -> 0 | BV15: =BS15+BT15-BU15 -> 0 | BY15: =BV15+BW15-BX15 -> 0 | CB15: =BY15+BZ15-CA15 -> 0 | CE15: =CB15+CC15-CD15 -> 0 | CH15: =CE15+CF15-CG15 -> 0 | CK15: =CH15+CI15-CJ15 -> 0 | CN15: =CK15+CL15-CM15 -> 0 | CQ15: =CN15+CO15-CP15 -> 0 | CT15: =CQ15+CR15-CS15 -> 0 | CW15: =CT15+CU15-CV15 -> 0 | CZ15: =CW15+CX15-CY15 -> 0 | DC15: =CZ15+DA15-DB15 -> 0 | DF15: =DC15+DD15-DE15 -> 0 | DI15: =DF15+DG15-DH15 -> 0
D16: =LOOKUP(2,1/(F16:DI16<>""),F16:DI16) -> 0 | H16: =F16-G16 -> 0 | K16: =H16+I16-J16 -> 0 | N16: =K16+L16-M16 -> 0 | Q16: =N16+O16-P16 -> 0 | T16: =Q16+R16-S16 -> 0 | W16: =T16+U16-V16 -> 0 | Z16: =W16+X16-Y16 -> 0 | AC16: =Z16+AA16-AB16 -> 0 | AF16: =AC16+AD16-AE16 -> 0 | AI16: =AF16+AG16-AH16 -> 0 | AL16: =AI16+AJ16-AK16 -> 0 | AO16: =AL16+AM16-AN16 -> 0 | AR16: =AO16+AP16-AQ16 -> 0 | AU16: =AR16+AS16-AT16 -> 0 | AX16: =AU16+AV16-AW16 -> 0 | BA16: =AX16+AY16-AZ16 -> 0 | BD16: =BA16+BB16-BC16 -> 0 | BG16: =BD16+BE16-BF16 -> 0 | BJ16: =BG16+BH16-BI16 -> 0 | BM16: =BJ16+BK16-BL16 -> 0 | BP16: =BM16+BN16-BO16 -> 0 | BS16: =BP16+BQ16-BR16 -> 0 | BV16: =BS16+BT16-BU16 -> 0 | BY16: =BV16+BW16-BX16 -> 0 | CB16: =BY16+BZ16-CA16 -> 0 | CE16: =CB16+CC16-CD16 -> 0 | CH16: =CE16+CF16-CG16 -> 0 | CK16: =CH16+CI16-CJ16 -> 0 | CN16: =CK16+CL16-CM16 -> 0 | CQ16: =CN16+CO16-CP16 -> 0 | CT16: =CQ16+CR16-CS16 -> 0 | CW16: =CT16+CU16-CV16 -> 0 | CZ16: =CW16+CX16-CY16 -> 0 | DC16: =CZ16+DA16-DB16 -> 0 | DF16: =DC16+DD16-DE16 -> 0 | DI16: =DF16+DG16-DH16 -> 0
D17: =LOOKUP(2,1/(F17:DI17<>""),F17:DI17) -> 0 | H17: =F17-G17 -> 0 | K17: =H17+I17-J17 -> 0 | N17: =K17+L17-M17 -> 0 | Q17: =N17+O17-P17 -> 0 | T17: =Q17+R17-S17 -> 0 | W17: =T17+U17-V17 -> 0 | Z17: =W17+X17-Y17 -> 0 | AC17: =Z17+AA17-AB17 -> 0 | AF17: =AC17+AD17-AE17 -> 0 | AI17: =AF17+AG17-AH17 -> 0 | AL17: =AI17+AJ17-AK17 -> 0 | AO17: =AL17+AM17-AN17 -> 0 | AR17: =AO17+AP17-AQ17 -> 0 | AU17: =AR17+AS17-AT17 -> 0 | AX17: =AU17+AV17-AW17 -> 0 | BA17: =AX17+AY17-AZ17 -> 0 | BD17: =BA17+BB17-BC17 -> 0 | BG17: =BD17+BE17-BF17 -> 0 | BJ17: =BG17+BH17-BI17 -> 0 | BM17: =BJ17+BK17-BL17 -> 0 | BP17: =BM17+BN17-BO17 -> 0 | BS17: =BP17+BQ17-BR17 -> 0 | BV17: =BS17+BT17-BU17 -> 0 | BY17: =BV17+BW17-BX17 -> 0 | CB17: =BY17+BZ17-CA17 -> 0 | CE17: =CB17+CC17-CD17 -> 0 | CH17: =CE17+CF17-CG17 -> 0 | CK17: =CH17+CI17-CJ17 -> 0 | CN17: =CK17+CL17-CM17 -> 0 | CQ17: =CN17+CO17-CP17 -> 0 | CT17: =CQ17+CR17-CS17 -> 0 | CW17: =CT17+CU17-CV17 -> 0 | CZ17: =CW17+CX17-CY17 -> 0 | DC17: =CZ17+DA17-DB17 -> 0 | DF17: =DC17+DD17-DE17 -> 0 | DI17: =DF17+DG17-DH17 -> 0
D18: =LOOKUP(2,1/(F18:DI18<>""),F18:DI18) -> 0 | H18: =F18-G18 -> 0 | K18: =H18+I18-J18 -> 0 | N18: =K18+L18-M18 -> 0 | Q18: =N18+O18-P18 -> 0 | T18: =Q18+R18-S18 -> 0 | W18: =T18+U18-V18 -> 0 | Z18: =W18+X18-Y18 -> 0 | AC18: =Z18+AA18-AB18 -> 0 | AF18: =AC18+AD18-AE18 -> 0 | AI18: =AF18+AG18-AH18 -> 0 | AL18: =AI18+AJ18-AK18 -> 0 | AO18: =AL18+AM18-AN18 -> 0 | AR18: =AO18+AP18-AQ18 -> 0 | AU18: =AR18+AS18-AT18 -> 0 | AX18: =AU18+AV18-AW18 -> 0 | BA18: =AX18+AY18-AZ18 -> 0 | BD18: =BA18+BB18-BC18 -> 0 | BG18: =BD18+BE18-BF18 -> 0 | BJ18: =BG18+BH18-BI18 -> 0 | BM18: =BJ18+BK18-BL18 -> 0 | BP18: =BM18+BN18-BO18 -> 0 | BS18: =BP18+BQ18-BR18 -> 0 | BV18: =BS18+BT18-BU18 -> 0 | BY18: =BV18+BW18-BX18 -> 0 | CB18: =BY18+BZ18-CA18 -> 0 | CE18: =CB18+CC18-CD18 -> 0 | CH18: =CE18+CF18-CG18 -> 0 | CK18: =CH18+CI18-CJ18 -> 0 | CN18: =CK18+CL18-CM18 -> 0 | CQ18: =CN18+CO18-CP18 -> 0 | CT18: =CQ18+CR18-CS18 -> 0 | CW18: =CT18+CU18-CV18 -> 0 | CZ18: =CW18+CX18-CY18 -> 0 | DC18: =CZ18+DA18-DB18 -> 0 | DF18: =DC18+DD18-DE18 -> 0 | DI18: =DF18+DG18-DH18 -> 0
D19: =LOOKUP(2,1/(F19:DI19<>""),F19:DI19) -> 0 | H19: =F19-G19 -> 0 | K19: =H19+I19-J19 -> 0 | N19: =K19+L19-M19 -> 0 | Q19: =N19+O19-P19 -> 0 | T19: =Q19+R19-S19 -> 0 | W19: =T19+U19-V19 -> 0 | Z19: =W19+X19-Y19 -> 0 | AC19: =Z19+AA19-AB19 -> 0 | AF19: =AC19+AD19-AE19 -> 0 | AI19: =AF19+AG19-AH19 -> 0 | AL19: =AI19+AJ19-AK19 -> 0 | AO19: =AL19+AM19-AN19 -> 0 | AR19: =AO19+AP19-AQ19 -> 0 | AU19: =AR19+AS19-AT19 -> 0 | AX19: =AU19+AV19-AW19 -> 0 | BA19: =AX19+AY19-AZ19 -> 0 | BD19: =BA19+BB19-BC19 -> 0 | BG19: =BD19+BE19-BF19 -> 0 | BJ19: =BG19+BH19-BI19 -> 0 | BM19: =BJ19+BK19-BL19 -> 0 | BP19: =BM19+BN19-BO19 -> 0 | BS19: =BP19+BQ19-BR19 -> 0 | BV19: =BS19+BT19-BU19 -> 0 | BY19: =BV19+BW19-BX19 -> 0 | CB19: =BY19+BZ19-CA19 -> 0 | CE19: =CB19+CC19-CD19 -> 0 | CH19: =CE19+CF19-CG19 -> 0 | CK19: =CH19+CI19-CJ19 -> 0 | CN19: =CK19+CL19-CM19 -> 0 | CQ19: =CN19+CO19-CP19 -> 0 | CT19: =CQ19+CR19-CS19 -> 0 | CW19: =CT19+CU19-CV19 -> 0 | CZ19: =CW19+CX19-CY19 -> 0 | DC19: =CZ19+DA19-DB19 -> 0 | DF19: =DC19+DD19-DE19 -> 0 | DI19: =DF19+DG19-DH19 -> 0
D20: =LOOKUP(2,1/(F20:DI20<>""),F20:DI20) -> 0 | H20: =F20-G20 -> 0 | K20: =H20+I20-J20 -> 0 | N20: =K20+L20-M20 -> 0 | Q20: =N20+O20-P20 -> 0 | T20: =Q20+R20-S20 -> 0 | W20: =T20+U20-V20 -> 0 | Z20: =W20+X20-Y20 -> 0 | AC20: =Z20+AA20-AB20 -> 0 | AF20: =AC20+AD20-AE20 -> 0 | AI20: =AF20+AG20-AH20 -> 0 | AL20: =AI20+AJ20-AK20 -> 0 | AO20: =AL20+AM20-AN20 -> 0 | AR20: =AO20+AP20-AQ20 -> 0 | AU20: =AR20+AS20-AT20 -> 0 | AX20: =AU20+AV20-AW20 -> 0 | BA20: =AX20+AY20-AZ20 -> 0 | BD20: =BA20+BB20-BC20 -> 0 | BG20: =BD20+BE20-BF20 -> 0 | BJ20: =BG20+BH20-BI20 -> 0 | BM20: =BJ20+BK20-BL20 -> 0 | BP20: =BM20+BN20-BO20 -> 0 | BS20: =BP20+BQ20-BR20 -> 0 | BV20: =BS20+BT20-BU20 -> 0 | BY20: =BV20+BW20-BX20 -> 0 | CB20: =BY20+BZ20-CA20 -> 0 | CE20: =CB20+CC20-CD20 -> 0 | CH20: =CE20+CF20-CG20 -> 0 | CK20: =CH20+CI20-CJ20 -> 0 | CN20: =CK20+CL20-CM20 -> 0 | CQ20: =CN20+CO20-CP20 -> 0 | CT20: =CQ20+CR20-CS20 -> 0 | CW20: =CT20+CU20-CV20 -> 0 | CZ20: =CW20+CX20-CY20 -> 0 | DC20: =CZ20+DA20-DB20 -> 0 | DF20: =DC20+DD20-DE20 -> 0 | DI20: =DF20+DG20-DH20 -> 0
D21: =SUM(D5:D20) -> 29 | H21: =F21-G21 -> 0 | K21: =H21+I21-J21 -> 0 | N21: =K21+L21-M21 -> 0 | Q21: =N21+O21-P21 -> 0 | T21: =Q21+R21-S21 -> 0 | W21: =T21+U21-V21 -> 0 | Z21: =W21+X21-Y21 -> 0 | AC21: =Z21+AA21-AB21 -> 0 | AF21: =AC21+AD21-AE21 -> 0 | AI21: =AF21+AG21-AH21 -> 0 | AL21: =AI21+AJ21-AK21 -> 0 | AO21: =AL21+AM21-AN21 -> 0 | AR21: =AO21+AP21-AQ21 -> 0 | AU21: =AR21+AS21-AT21 -> 0 | AX21: =AU21+AV21-AW21 -> 0 | BA21: =AX21+AY21-AZ21 -> 0 | BD21: =BA21+BB21-BC21 -> 0 | BG21: =BD21+BE21-BF21 -> 0 | BJ21: =BG21+BH21-BI21 -> 0 | BM21: =BJ21+BK21-BL21 -> 0 | BP21: =BM21+BN21-BO21 -> 0 | BS21: =BP21+BQ21-BR21 -> 0 | BV21: =BS21+BT21-BU21 -> 0 | BY21: =BV21+BW21-BX21 -> 0 | CB21: =BY21+BZ21-CA21 -> 0 | CE21: =CB21+CC21-CD21 -> 0 | CH21: =CE21+CF21-CG21 -> 0 | CK21: =CH21+CI21-CJ21 -> 0 | CN21: =CK21+CL21-CM21 -> 0 | CQ21: =CN21+CO21-CP21 -> 0 | CT21: =CQ21+CR21-CS21 -> 0 | CW21: =CT21+CU21-CV21 -> 0 | CZ21: =CW21+CX21-CY21 -> 0 | DC21: =CZ21+DA21-DB21 -> 0 | DF21: =DC21+DD21-DE21 -> 0 | DI21: =DF21+DG21-DH21 -> 0
A22: Digestion Mix 2kg
A23: Herbal Horse & Pet | B23: 180320261HHPDM | C23: 18/03/2028 | D23: =LOOKUP(2,1/(F23:DI23<>""),F23:DI23) -> 5 | F23: 0 | H23: =F23-G23 -> 0 | K23: =H23+I23-J23 -> 0 | L23: 5 | N23: =K23+L23-M23 -> 5 | Q23: =N23+O23-P23 -> 5 | T23: =Q23+R23-S23 -> 5 | W23: =T23+U23-V23 -> 5 | Z23: =W23+X23-Y23 -> 5 | AC23: =Z23+AA23-AB23 -> 5 | AF23: =AC23+AD23-AE23 -> 5 | AI23: =AF23+AG23-AH23 -> 5 | AL23: =AI23+AJ23-AK23 -> 5 | AO23: =AL23+AM23-AN23 -> 5 | AR23: =AO23+AP23-AQ23 -> 5 | AU23: =AR23+AS23-AT23 -> 5 | AX23: =AU23+AV23-AW23 -> 5 | BA23: =AX23+AY23-AZ23 -> 5 | BD23: =BA23+BB23-BC23 -> 5 | BG23: =BD23+BE23-BF23 -> 5 | BJ23: =BG23+BH23-BI23 -> 5 | BM23: =BJ23+BK23-BL23 -> 5 | BP23: =BM23+BN23-BO23 -> 5 | BS23: =BP23+BQ23-BR23 -> 5 | BV23: =BS23+BT23-BU23 -> 5 | BY23: =BV23+BW23-BX23 -> 5 | CB23: =BY23+BZ23-CA23 -> 5 | CE23: =CB23+CC23-CD23 -> 5 | CH23: =CE23+CF23-CG23 -> 5 | CK23: =CH23+CI23-CJ23 -> 5 | CN23: =CK23+CL23-CM23 -> 5 | CQ23: =CN23+CO23-CP23 -> 5 | CT23: =CQ23+CR23-CS23 -> 5 | CW23: =CT23+CU23-CV23 -> 5 | CZ23: =CW23+CX23-CY23 -> 5 | DC23: =CZ23+DA23-DB23 -> 5 | DF23: =DC23+DD23-DE23 -> 5 | DI23: =DF23+DG23-DH23 -> 5
A24: Current STOCK | D24: =LOOKUP(2,1/(F24:DI24<>""),F24:DI24) -> 0 | H24: =F24-G24 -> 0 | K24: =H24+I24-J24 -> 0 | N24: =K24+L24-M24 -> 0 | Q24: =N24+O24-P24 -> 0 | T24: =Q24+R24-S24 -> 0 | W24: =T24+U24-V24 -> 0 | Z24: =W24+X24-Y24 -> 0 | AC24: =Z24+AA24-AB24 -> 0 | AF24: =AC24+AD24-AE24 -> 0 | AI24: =AF24+AG24-AH24 -> 0 | AL24: =AI24+AJ24-AK24 -> 0 | AO24: =AL24+AM24-AN24 -> 0 | AR24: =AO24+AP24-AQ24 -> 0 | AU24: =AR24+AS24-AT24 -> 0 | AX24: =AU24+AV24-AW24 -> 0 | BA24: =AX24+AY24-AZ24 -> 0 | BD24: =BA24+BB24-BC24 -> 0 | BG24: =BD24+BE24-BF24 -> 0 | BJ24: =BG24+BH24-BI24 -> 0 | BM24: =BJ24+BK24-BL24 -> 0 | BP24: =BM24+BN24-BO24 -> 0 | BS24: =BP24+BQ24-BR24 -> 0 | BV24: =BS24+BT24-BU24 -> 0 | BY24: =BV24+BW24-BX24 -> 0 | CB24: =BY24+BZ24-CA24 -> 0 | CE24: =CB24+CC24-CD24 -> 0 | CH24: =CE24+CF24-CG24 -> 0 | CK24: =CH24+CI24-CJ24 -> 0 | CN24: =CK24+CL24-CM24 -> 0 | CQ24: =CN24+CO24-CP24 -> 0 | CT24: =CQ24+CR24-CS24 -> 0 | CW24: =CT24+CU24-CV24 -> 0 | CZ24: =CW24+CX24-CY24 -> 0 | DC24: =CZ24+DA24-DB24 -> 0 | DF24: =DC24+DD24-DE24 -> 0 | DI24: =DF24+DG24-DH24 -> 0
A25: =D39 -> 5 | D25: =LOOKUP(2,1/(F25:DI25<>""),F25:DI25) -> 0 | H25: =F25-G25 -> 0 | K25: =H25+I25-J25 -> 0 | N25: =K25+L25-M25 -> 0 | Q25: =N25+O25-P25 -> 0 | T25: =Q25+R25-S25 -> 0 | W25: =T25+U25-V25 -> 0 | Z25: =W25+X25-Y25 -> 0 | AC25: =Z25+AA25-AB25 -> 0 | AF25: =AC25+AD25-AE25 -> 0 | AI25: =AF25+AG25-AH25 -> 0 | AL25: =AI25+AJ25-AK25 -> 0 | AO25: =AL25+AM25-AN25 -> 0 | AR25: =AO25+AP25-AQ25 -> 0 | AU25: =AR25+AS25-AT25 -> 0 | AX25: =AU25+AV25-AW25 -> 0 | BA25: =AX25+AY25-AZ25 -> 0 | BD25: =BA25+BB25-BC25 -> 0 | BG25: =BD25+BE25-BF25 -> 0 | BJ25: =BG25+BH25-BI25 -> 0 | BM25: =BJ25+BK25-BL25 -> 0 | BP25: =BM25+BN25-BO25 -> 0 | BS25: =BP25+BQ25-BR25 -> 0 | BV25: =BS25+BT25-BU25 -> 0 | BY25: =BV25+BW25-BX25 -> 0 | CB25: =BY25+BZ25-CA25 -> 0 | CE25: =CB25+CC25-CD25 -> 0 | CH25: =CE25+CF25-CG25 -> 0 | CK25: =CH25+CI25-CJ25 -> 0 | CN25: =CK25+CL25-CM25 -> 0 | CQ25: =CN25+CO25-CP25 -> 0 | CT25: =CQ25+CR25-CS25 -> 0 | CW25: =CT25+CU25-CV25 -> 0 | CZ25: =CW25+CX25-CY25 -> 0 | DC25: =CZ25+DA25-DB25 -> 0 | DF25: =DC25+DD25-DE25 -> 0 | DI25: =DF25+DG25-DH25 -> 0
D26: =LOOKUP(2,1/(F26:DI26<>""),F26:DI26) -> 0 | H26: =F26-G26 -> 0 | K26: =H26+I26-J26 -> 0 | N26: =K26+L26-M26 -> 0 | Q26: =N26+O26-P26 -> 0 | T26: =Q26+R26-S26 -> 0 | W26: =T26+U26-V26 -> 0 | Z26: =W26+X26-Y26 -> 0 | AC26: =Z26+AA26-AB26 -> 0 | AF26: =AC26+AD26-AE26 -> 0 | AI26: =AF26+AG26-AH26 -> 0 | AL26: =AI26+AJ26-AK26 -> 0 | AO26: =AL26+AM26-AN26 -> 0 | AR26: =AO26+AP26-AQ26 -> 0 | AU26: =AR26+AS26-AT26 -> 0 | AX26: =AU26+AV26-AW26 -> 0 | BA26: =AX26+AY26-AZ26 -> 0 | BD26: =BA26+BB26-BC26 -> 0 | BG26: =BD26+BE26-BF26 -> 0 | BJ26: =BG26+BH26-BI26 -> 0 | BM26: =BJ26+BK26-BL26 -> 0 | BP26: =BM26+BN26-BO26 -> 0 | BS26: =BP26+BQ26-BR26 -> 0 | BV26: =BS26+BT26-BU26 -> 0 | BY26: =BV26+BW26-BX26 -> 0 | CB26: =BY26+BZ26-CA26 -> 0 | CE26: =CB26+CC26-CD26 -> 0 | CH26: =CE26+CF26-CG26 -> 0 | CK26: =CH26+CI26-CJ26 -> 0 | CN26: =CK26+CL26-CM26 -> 0 | CQ26: =CN26+CO26-CP26 -> 0 | CT26: =CQ26+CR26-CS26 -> 0 | CW26: =CT26+CU26-CV26 -> 0 | CZ26: =CW26+CX26-CY26 -> 0 | DC26: =CZ26+DA26-DB26 -> 0 | DF26: =DC26+DD26-DE26 -> 0 | DI26: =DF26+DG26-DH26 -> 0
D27: =LOOKUP(2,1/(F27:DI27<>""),F27:DI27) -> 0 | H27: =F27-G27 -> 0 | K27: =H27+I27-J27 -> 0 | N27: =K27+L27-M27 -> 0 | Q27: =N27+O27-P27 -> 0 | T27: =Q27+R27-S27 -> 0 | W27: =T27+U27-V27 -> 0 | Z27: =W27+X27-Y27 -> 0 | AC27: =Z27+AA27-AB27 -> 0 | AF27: =AC27+AD27-AE27 -> 0 | AI27: =AF27+AG27-AH27 -> 0 | AL27: =AI27+AJ27-AK27 -> 0 | AO27: =AL27+AM27-AN27 -> 0 | AR27: =AO27+AP27-AQ27 -> 0 | AU27: =AR27+AS27-AT27 -> 0 | AX27: =AU27+AV27-AW27 -> 0 | BA27: =AX27+AY27-AZ27 -> 0 | BD27: =BA27+BB27-BC27 -> 0 | BG27: =BD27+BE27-BF27 -> 0 | BJ27: =BG27+BH27-BI27 -> 0 | BM27: =BJ27+BK27-BL27 -> 0 | BP27: =BM27+BN27-BO27 -> 0 | BS27: =BP27+BQ27-BR27 -> 0 | BV27: =BS27+BT27-BU27 -> 0 | BY27: =BV27+BW27-BX27 -> 0 | CB27: =BY27+BZ27-CA27 -> 0 | CE27: =CB27+CC27-CD27 -> 0 | CH27: =CE27+CF27-CG27 -> 0 | CK27: =CH27+CI27-CJ27 -> 0 | CN27: =CK27+CL27-CM27 -> 0 | CQ27: =CN27+CO27-CP27 -> 0 | CT27: =CQ27+CR27-CS27 -> 0 | CW27: =CT27+CU27-CV27 -> 0 | CZ27: =CW27+CX27-CY27 -> 0 | DC27: =CZ27+DA27-DB27 -> 0 | DF27: =DC27+DD27-DE27 -> 0 | DI27: =DF27+DG27-DH27 -> 0
